Workbook

Sheet DataShee
A1: COMPANY NAME | B1: UNITED SPIRITS LTD | E1: =IF(B2<>B3, "A NEW VERSION OF THE WORKSHEET IS AVAILABLE", "")
A2: LATEST VERSION | B2: 2.1 | E2: PLEASE DO NOT MAKE ANY CHANGES TO THIS SHEET
A3: CURRENT VERSION | B3: 2.1
A5: META
A6: Number of shares | B6: =IF(B9>0, B9/B8, 0)
A7: Face Value | B7: 2
A8: Current Price | B8: 1320.7
A9: Market Capitalization | B9: 96061.23
A15: PROFIT & LOSS
A16: Report Date | B16: 42825 | C16: 43190 | D16: 43555 | E16: 43921 | F16: 44286 | G16: 44651 | H16: 45016 | I16: 45382 | J16: 45747 | K16: 46112
A17: Sales | B17: 8817.5 | C17: 8590.6 | D17: 9340.8 | E17: 9325.4 | F17: 8131.3 | G17: 9712.4 | H17: 10612 | I17: 11321 | J17: 12069 | K17: 12467
A18: Raw Material Cost | B18: 3053.5 | C18: 2679 | D18: 2940.4 | E18: 3435.1 | F18: 2812.9 | G18: 3519.6 | H18: 4361 | I18: 3937 | J18: 4179 | K18: 6815
A19: Change in Inventory | B19: 56.8 | C19: -14.1 | D19: 65.7 | E19: 98.4 | F19: 133.1 | G19: -82.7 | H19: -137 | I19: 119 | J19: 90 | K19: -141
A20: Power and Fuel | B20: 34.8 | C20: 27.9 | D20: 24.9 | E20: 24.5 | F20: 20 | G20: 18.2 | H20: 17 | I20: 18 | J20: 19
A21: Other Mfr. Exp | B21: 2006.2 | C21: 1864.5 | D21: 1935.4 | E21: 1812 | F21: 1841.5 | G21: 2225.8 | H21: 2262 | I21: 2468 | J21: 2572
A22: Employee Cost | B22: 688.9 | C22: 681.2 | D22: 690.2 | E22: 530.4 | F22: 557 | G22: 653.9 | H22: 613 | I22: 549 | J22: 614 | K22: 635
A23: Selling and admin | B23: 1862.2 | C23: 1963.8 | D23: 2106.3 | E23: 1875 | F23: 1625.7 | G23: 1710 | H23: 2024 | I23: 1966 | J23: 2135 | K23: 1295
A24: Other Expenses | B24: 123.7 | C24: 179.1 | D24: 184.1 | E24: -21 | F24: 89.7 | G24: 72.4 | H24: 55 | I24: 264 | J24: 224 | K24: 1584
A25: Other Income | B25: -265 | C25: 172.4 | D25: 69.8 | E25: 86.6 | F25: -24.7 | G25: -116.8 | H25: 249 | I25: 208 | J25: 271 | K25: 516
A26: Depreciation | B26: 188.6 | C26: 192.3 | D26: 214.7 | E26: 285.3 | F26: 299.1 | G26: 303.8 | H26: 283 | I26: 275 | J26: 283 | K26: 289
A27: Interest | B27: 375.1 | C27: 277.5 | D27: 237.2 | E27: 212 | F27: 187.6 | G27: 88 | H27: 104 | I27: 76 | J27: 89 | K27: 158
A28: Profit before tax | B28: 162.7 | C28: 911.8 | D28: 1011.7 | E28: 1160.3 | F28: 540 | G28: 1086.6 | H28: 1279 | I28: 1857 | J28: 2135 | K28: 2348
A29: Tax | B29: 69.7 | C29: 259.9 | D29: 328.1 | E29: 539.7 | F29: 177.9 | G29: 276 | H29: 153 | I29: 449 | J29: 553 | K29: 510
A30: Net profit | B30: 100.1 | C30: 633.8 | D30: 700.2 | E30: 658.9 | F30: 383.6 | G30: 828.6 | H30: 1137 | I30: 1408 | J30: 1582 | K30: 1838
A31: Dividend Amount | I31: 652.5 | J31: 870 | K31: 797.5
E33: =SUM(E18:E24)+E26+E27
A40: Quarters
A41: Report Date | B41: 45291 | C41: 45382 | D41: 45473 | E41: 45565 | F41: 45657 | G41: 45747 | H41: 45838 | I41: 45930 | J41: 46022 | K41: 46112
A42: Sales | B42: 3002 | C42: 2783 | D42: 2761 | E42: 2844 | F42: 3433 | G42: 2946 | H42: 3021 | I42: 3173 | J42: 3691 | K42: 3054
A43: Expenses | B43: 2516 | C43: 2449 | D43: 2049 | E43: 2344 | F43: 2868 | G43: 2437 | H43: 2383 | I43: 2514 | J43: 3077 | K43: 2461
A44: Other Income | B44: 52 | C44: 80 | D44: 35 | E44: 54 | F44: 7 | G44: 136 | H44: 58 | I44: 51 | J44: 28 | K44: 226
A45: Depreciation | B45: 63 | C45: 73 | D45: 72 | E45: 69 | F45: 72 | G45: 70 | H45: 76 | I45: 65 | J45: 80 | K45: 76
A46: Interest | B46: 16 | C46: 29 | D46: 22 | E46: 25 | F46: 20 | G46: 22 | H46: 49 | I46: 21 | J46: 19 | K46: 69
A47: Profit before tax | B47: 459 | C47: 312 | D47: 653 | E47: 460 | F47: 480 | G47: 553 | H47: 571 | I47: 624 | J47: 543 | K47: 674
A48: Tax | B48: 109 | C48: 71 | D48: 168 | E48: 119 | F48: 145 | G48: 132 | H48: 154 | I48: 160 | J48: 125 | K48: 135
A49: Net profit | B49: 350 | C49: 241 | D49: 485 | E49: 341 | F49: 335 | G49: 421 | H49: 417 | I49: 464 | J49: 418 | K49: 539
A50: Operating Profit | B50: 486 | C50: 334 | D50: 712 | E50: 500 | F50: 565 | G50: 509 | H50: 638 | I50: 659 | J50: 614 | K50: 593
A55: BALANCE SHEET
A56: Report Date | B56: 42825 | C56: 43190 | D56: 43555 | E56: 43921 | F56: 44286 | G56: 44651 | H56: 45016 | I56: 45382 | J56: 45747 | K56: 46112
A57: Equity Share Capital | B57: 145.3 | C57: 145.3 | D57: 145.3 | E57: 145.3 | F57: 145.3 | G57: 145.3 | H57: 145 | I57: 145 | J57: 145 | K57: 145
...

Sheet Scenarios
C2: United Spirits Economic Scenarios
C4: Scenario Switch | D4: 1
C8: Sales Growth % Scenarios | H8: 2027 | I8: =H8+1 | J8: =I8+1 | K8: =J8+1 | L8: =K8+1 | M8: =L8+1 | N8: =M8+1 | O8: =N8+1
C10: Sales Growth % | H10: =CHOOSE($D$4,H12,H13,H14) | I10: =CHOOSE($D$4,I12,I13,I14) | J10: =CHOOSE($D$4,J12,J13,J14) | K10: =CHOOSE($D$4,K12,K13,K14) | L10: =CHOOSE($D$4,L12,L13,L14) | M10: =CHOOSE($D$4,M12,M13,M14) | N10: =CHOOSE($D$4,N12,N13,N14) | O10: =CHOOSE($D$4,O12,O13,O14)
C12: Base | H12: 0.09 | I12: 0.08 | J12: 0.07 | K12: 0.07 | L12: 0.07 | M12: 0.065 | N12: 0.06 | O12: 0.06
C13: Best | H13: 0.11 | I13: 0.1 | J13: 0.09 | K13: 0.08 | L13: 0.08 | M13: 0.07 | N13: 0.07 | O13: 0.06
C14: Bear | H14: 0.06 | I14: 0.06 | J14: 0.05 | K14: 0.05 | L14: 0.05 | M14: 0.045 | N14: 0.04 | O14: 0.04
C17: Gross Profit Margin % Scenarios | H17: 2027 | I17: =H17+1 | J17: =I17+1 | K17: =J17+1 | L17: =K17+1 | M17: =L17+1 | N17: =M17+1 | O17: =N17+1
C19: Gross Profi Margin % | H19: =CHOOSE($D$4,H21,H22,H23) | I19: =CHOOSE($D$4,I21,I22,I23) | J19: =CHOOSE($D$4,J21,J22,J23) | K19: =CHOOSE($D$4,K21,K22,K23) | L19: =CHOOSE($D$4,L21,L22,L23) | M19: =CHOOSE($D$4,M21,M22,M23) | N19: =CHOOSE($D$4,N21,N22,N23) | O19: =CHOOSE($D$4,O21,O22,O23)
C21: Base | H21: 0.455 | I21: 0.46 | J21: 0.465 | K21: 0.47 | L21: 0.47 | M21: 0.475 | N21: 0.475 | O21: 0.48
C22: Best | H22: 0.46720587 | I22: 0.48156147 | J22: 0.49591708 | K22: 0.51027268 | L22: 0.515 | M22: 0.52 | N22: 0.52 | O22: 0.52
C23: Bear | H23: 0.435 | I23: 0.435 | J23: 0.44 | K23: 0.44 | L23: 0.44 | M23: 0.44 | N23: 0.44 | O23: 0.44

Sheet Comparables
B2: Peer Comparison
A3: x | C3: Assumptions
C4: Revenue | D4: EBITDA | E4: EBIT | F4: PAT
B5: United Breweries | C5: 0.08 | D5: 0.089177489 | E5: 0.062662338 | F5: 0.04469697
B6: Radico Khaitan Ltd | C6: 0.25 | D6: 0.17157025 | E6: 0.14644628 | F6: 0.10198347
B7: Allied Blenders | C7: 0.08 | D7: 0.13815957 | E7: 0.12413969 | F7: 0.058373694
C9: 2026 | J9: =C9+1 | O9: =J9+1
A11: x | B11: Particulars | C11: Mkt Cap | D11: EV | E11: Revenue | F11: EBITDA | G11: EBIT | H11: PAT | J11: Revenue | K11: EBITDA | L11: EBIT | M11: PAT | O11: Revenue | P11: EBITDA | Q11: EBIT | R11: PAT
B12: United Spirits | C12: 96196 | D12: 94632 | E12: 12467 | F12: 2279 | G12: 1990 | H12: 1838 | J12: 13589.03 | K12: 2547.3242 | L12: 2351.1612 | M12: 1846.9939 | O12: 14676.152 | P12: 2824.4908 | Q12: 2585.3019 | R12: 2023.5883
B13: United Breweries | C13: 35605 | D13: 36350 | E13: 9240 | F13: 824 | G13: 579 | H13: 413 | J13: =E13*(1+C5) | K13: =J13*D5 | L13: =J13*E5 | M13: =J13*F5 | O13: =J13*(1+C5) | P13: =$O$13*D5 | Q13: =$O$13*E5 | R13: =$O$13*F5
B14: Radico Khaitan Ltd | C14: 50274 | D14: 50883 | E14: 6050 | F14: 1038 | G14: 886 | H14: 617 | J14: =E14*(1+C6) | K14: =J14*D6 | L14: =J14*E6 | M14: =J14*F6 | O14: =J14*(1+C6) | P14: =$O$14*D6 | Q14: =$O$14*E6 | R14: =$O$14*F6
B15: Allied Blenders | C15: 17640 | D15: 18635 | E15: 3923 | F15: 542 | G15: 487 | H15: 229 | J15: =E15*(1+C7) | K15: =J15*D7 | L15: =J15*E7 | M15: =J15*F7 | O15: =J15*(1+C7) | P15: =$O$15*D7 | Q15: =$O$15*E7 | R15: =$O$15*F7
A18: x | B18: Multiples
E19: 2026 | J19: =1+E19 | O19: =J19+1
B21: Particulars | E21: EV/Revenue | F21: EV/EBITDA | G21: EV/EBIT | H21: P/E | J21: EV/Revenue | K21: EV/EBITDA | L21: EV/EBIT | M21: P/E | O21: EV/Revenue | P21: EV/EBITDA | Q21: EV/EBIT | R21: P/E
A22: x | B22: United Spirits | E22: =$D$12/E12 | F22: =$D$12/F12 | G22: =$D$12/G12 | H22: =$C$12/H12 | J22: =$D$12/J12 | K22: =$D$12/K12 | L22: =$D$12/L12 | M22: =$C$12/M12 | O22: =$D$12/O12 | P22: =$D$12/P12 | Q22: =$D$12/Q12 | R22: =$C$12/R12
B23: United Breweries | E23: =$D$13/E13 | F23: =$D$13/F13 | G23: =$D$13/G13 | H23: =$C$13/H13 | J23: =$D$13/J13 | K23: =$D$13/K13 | L23: =$D$13/L13 | M23: =$C$13/M13 | O23: =$D$13/O13 | P23: =$D$13/P13 | Q23: =$D$13/Q13 | R23: =$C$13/R13
B24: Radico Khaitan Ltd | E24: =$D$14/E14 | F24: =$D$14/F14 | G24: =$D$14/G14 | H24: =$C$14/H14 | J24: =$D$14/J14 | K24: =$D$14/K14 | L24: =$D$14/L14 | M24: =$C$14/M14 | O24: =$D$14/O14 | P24: =$D$14/P14 | Q24: =$D$14/Q14 | R24: =$C$14/R14
B25: Allied Blenders | E25: =$D$15/E15 | F25: =$D$15/F15 | G25: =$D$15/G15 | H25: =$C$15/H15 | J25: =$D$15/J15 | K25: =$D$15/K15 | L25: =$D$15/L15 | M25: =$C$15/M15 | O25: =$D$15/O15 | P25: =$D$15/P15 | Q25: =$D$15/Q15 | R25: =$C$15/R15
B27: Mean | E27: =AVERAGE(E23:E25) | F27: =AVERAGE(F23:F25) | G27: =AVERAGE(G23:G25) | H27: =AVERAGE(H23:H25) | J27: =AVERAGE(J23:J25) | K27: =AVERAGE(K23:K25) | L27: =AVERAGE(L23:L25) | M27: =AVERAGE(M23:M25) | O27: =AVERAGE(O23:O25) | P27: =AVERAGE(P23:P25) | Q27: =AVERAGE(Q23:Q25) | R27: =AVERAGE(R23:R25)
B28: Median | E28: =MEDIAN(E23:E25) | F28: =MEDIAN(F23:F25) | G28: =MEDIAN(G23:G25) | H28: =MEDIAN(H23:H25) | J28: =MEDIAN(J23:J25) | K28: =MEDIAN(K23:K25) | L28: =MEDIAN(L23:L25) | M28: =MEDIAN(M23:M25) | O28: =MEDIAN(O23:O25) | P28: =MEDIAN(P23:P25) | Q28: =MEDIAN(Q23:Q25) | R28: =MEDIAN(R23:R25)
B29: Lower Quartile | E29: =QUARTILE(E23:E25,1) | F29: =QUARTILE(F23:F25,1) | G29: =QUARTILE(G23:G25,1) | H29: =QUARTILE(H23:H25,1) | J29: =QUARTILE(J23:J25,1) | K29: =QUARTILE(K23:K25,1) | L29: =QUARTILE(L23:L25,1) | M29: =QUARTILE(M23:M25,1) | O29: =QUARTILE(O23:O25,1) | P29: =QUARTILE(P23:P25,1) | Q29: =QUARTILE(Q23:Q25,1) | R29: =QUARTILE(R23:R25,1)
A30: x | B30: Upper Quartile | E30: =QUARTILE(E23:E25,3) | F30: =QUARTILE(F23:F25,3) | G30: =QUARTILE(G23:G25,3) | H30: =QUARTILE(H23:H25,3) | J30: =QUARTILE(J23:J25,3) | K30: =QUARTILE(K23:K25,3) | L30: =QUARTILE(L23:L25,3) | M30: =QUARTILE(M23:M25,3) | O30: =QUARTILE(O23:O25,3) | P30: =QUARTILE(P23:P25,3) | Q30: =QUARTILE(Q23:Q25,3) | R30: =QUARTILE(R23:R25,3)
A33: x | B33: Valuation using Mean Multiples
E34: 2026 | J34: =1+E34 | O34: =J34+1
E36: EV/Revenue | F36: EV/EBITDA | G36: EV/EBIT | H36: P/E | J36: EV/Revenue | K36: EV/EBITDA | L36: EV/EBIT | M36: P/E | O36: EV/Revenue | P36: EV/EBITDA | Q36: EV/EBIT | R36: P/E
B37: Enterprise Value & Market Cap(P/E) | E37: =E27*E12 | F37: =F27*F12 | G37: =G27*G12 | H37: =H27*H12 | J37: =J27*J12 | K37: =K27*K12 | L37: =L27*L12 | M37: =M27*M12 | O37: =O27*O12 | P37: =P27*P12 | Q37: =Q27*Q12 | R37: =R27*R12
B38: Debt | E38: 407 | F38: 407 | G38: 407 | J38: 407 | K38: 407 | L38: 407 | O38: 407 | P38: 407 | Q38: 407
B39: Cash | E39: 3134 | F39: 3134 | G39: 3134 | J39: 3134 | K39: 3134 | L39: 3134 | O39: 3134 | P39: 3134 | Q39: 3134
B40: Equity Value | E40: =E37-E38+E39 | F40: =F37-F38+F39 | G40: =G37-G38+G39 | J40: =J37-J38+J39 | K40: =K37-K38+K39 | L40: =L37-L38+L39 | O40: =O37-O38+O39 | P40: =P37-P38+P39 | Q40: =Q37-Q38+Q39
B41: Shares O/S | E41: 72.74 | F41: 72.74 | G41: 72.74 | H41: 72.74 | J41: 72.74 | K41: 72.74 | L41: 72.74 | M41: 72.74 | O41: 72.74 | P41: 72.74 | Q41: 72.74 | R41: 72.74
A42: x | B42: Per Share Value | E42: =E40/E41 | F42: =F40/F41 | G42: =G40/G41 | H42: =H37/H41 | J42: =J40/J41 | K42: =K40/K41 | L42: =L40/L41 | M42: =M37/M41 | O42: =O40/O41 | P42: =P40/P41 | Q42: =Q40/Q41 | R42: =R37/R41
B45: Valuation using Median Multiples
E46: 2026 | J46: =1+E46 | O46: =J46+1
E48: EV/Revenue | F48: EV/EBITDA | G48: EV/EBIT | H48: P/E | J48: EV/Revenue | K48: EV/EBITDA | L48: EV/EBIT | M48: P/E | O48: EV/Revenue | P48: EV/EBITDA | Q48: EV/EBIT | R48: P/E
B49: Enterprise Value & Market Cap(P/E) | E49: =E28*E12 | F49: =F28*F12 | G49: =G28*G12 | H49: =H28*H12 | J49: =J28*J12 | K49: =K28*K12 | L49: =L28*L12 | M49: =M28*M12 | O49: =O28*O12 | P49: =P28*P12 | Q49: =Q28*Q12 | R49: =R28*R12
B50: Debt | E50: 407 | F50: 407 | G50: 407 | J50: 407 | K50: 407 | L50: 407 | O50: 407 | P50: 407 | Q50: 407
B51: Cash | E51: 3134 | F51: 3134 | G51: 3134 | J51: 3134 | K51: 3134 | L51: 3134 | O51: 3134 | P51: 3134 | Q51: 3134
B52: Equity Value | E52: =E49-E50+E51 | F52: =F49-F50+F51 | G52: =G49-G50+G51 | J52: =J49-J50+J51 | K52: =K49-K50+K51 | L52: =L49-L50+L51 | O52: =O49-O50+O51 | P52: =P49-P50+P51 | Q52: =Q49-Q50+Q51
B53: Shares O/S | E53: 72.74 | F53: 72.74 | G53: 72.74 | H53: 72.74 | J53: 72.74 | K53: 72.74 | L53: 72.74 | M53: 72.74 | O53: 72.74 | P53: 72.74 | Q53: 72.74 | R53: 72.74
...

Sheet Assumptions
B2: Assumptions
B4: Particulars | E4: 2027 | F4: =E4+1 | G4: =F4+1 | H4: =G4+1 | I4: =H4+1 | J4: =I4+1 | K4: =J4+1 | L4: =K4+1
B6: Cost of Goods Sold(COGS)
B7: Employee Cost as % of Sales | E7: 0.06254555 | F7: 0.06254555 | G7: 0.06254555 | H7: 0.06254555 | I7: 0.06254555 | J7: 0.06254555 | K7: 0.06254555 | L7: 0.06254555 | N7: Median of Last 10 Years
B8: Selling and admin as % of Sales | E8: 0.205 | F8: 0.205 | G8: 0.205 | H8: 0.205 | I8: 0.205 | J8: 0.205 | K8: 0.205 | L8: 0.205 | N8: Median of Last 10 Years
B9: Interest Income | E9: 0.065 | F9: 0.065 | G9: 0.065 | H9: 0.065 | I9: 0.065 | J9: 0.065 | K9: 0.065 | L9: 0.065 | N9: Market Yield on MFs, Depoists, investments
B10: Tax Rate | E10: 0.25 | F10: 0.25 | G10: 0.25 | H10: 0.25 | I10: 0.25 | J10: 0.25 | K10: 0.25 | L10: 0.25
B11: Dividend Payout Ratio | E11: 0.67 | F11: 0.67 | G11: 0.67 | H11: 0.67 | I11: 0.67 | J11: 0.67 | K11: 0.67 | L11: 0.67 | N11: Constant FY 26
B12: Total capex as % of NSV | E12: 0.015 | F12: 0.015 | G12: 0.015 | H12: 0.015 | I12: 0.015 | J12: 0.015 | K12: 0.015 | L12: 0.015 | N12: Median of last 5 years
B13: PPE Capex as % of NSV | E13: 0.014 | F13: 0.014 | G13: 0.014 | H13: 0.014 | I13: 0.014 | J13: 0.014 | K13: 0.014 | L13: 0.014 | N13: Median of last 4 years
B14: Amortisation as % of Opening Balance | E14: 0.04 | F14: 0.04 | G14: 0.04 | H14: 0.04 | I14: 0.04 | J14: 0.04 | K14: 0.04 | L14: 0.04 | N14: Median of last 5 years
B15: ROU additions as % of NSV | E15: 0.022 | F15: 0.022 | G15: 0.022 | H15: 0.022 | I15: 0.022 | J15: 0.022 | K15: 0.022 | L15: 0.022 | N15: Median of last 4 years
B16: ROU amortisation as % of (opening + 1/2 additions) | E16: 0.3 | F16: 0.3 | G16: 0.3 | H16: 0.3 | I16: 0.3 | J16: 0.3 | K16: 0.3 | L16: 0.3
B17: Depreciation useful life | E17: 16 | F17: 16 | G17: 16 | H17: 16 | I17: 16 | J17: 16 | K17: 16 | L17: 16 | N17: 1/6.2%(Average of last 5 years)
B18: Principal Reyament | E18: 0.07 | F18: 0.07 | G18: 0.07 | H18: 0.07 | I18: 0.07 | J18: 0.07 | K18: 0.07 | L18: 0.07 | N18: Historical median of last 4 years
B19: Interest rate on lease liabilities | E19: 0.085 | F19: 0.085 | G19: 0.085 | H19: 0.085 | I19: 0.085 | J19: 0.085 | K19: 0.085 | L19: 0.085 | N19: Historical median intt rate of last 4 years
B20: Interest rate on borrowings | E20: 0 | F20: 0 | G20: 0 | H20: 0 | I20: 0 | J20: 0 | K20: 0 | L20: 0
B21: Interest others | E21: 55 | F21: 55 | G21: 55 | H21: 55 | I21: 55 | J21: 55 | K21: 55 | L21: 55 | N21: Median of last 5 years
B22: Trade Payables | E22: 111 | F22: 111 | G22: 111 | H22: 111 | I22: 111 | J22: 111 | K22: 111 | L22: 111 | N22: Median of last 3 Years
B23: ST Provisions as % of Sales | E23: 0.044 | F23: 0.044 | G23: 0.044 | H23: 0.044 | I23: 0.044 | J23: 0.044 | K23: 0.044 | L23: 0.044 | N23: Average of Last 9 years
B24: Other Current Liabilities as % of Sales | E24: 0.16 | F24: 0.16 | G24: 0.16 | H24: 0.16 | I24: 0.16 | J24: 0.16 | K24: 0.16 | L24: 0.16 | N24: Median of last 10years
B25: Accounts Receivables days | E25: 97 | F25: 97 | G25: 97 | H25: 97 | I25: 97 | J25: 97 | K25: 97 | L25: 97 | N25: Historical Median of Last 10 Years
B26: Inventory Days | E26: 135 | F26: 135 | G26: 135 | H26: 135 | I26: 135 | J26: 135 | K26: 135 | L26: 135 | N26: Historical Median of Last 10 Years
B27: Other Current assets as % of Sales | E27: 0.055 | F27: 0.055 | G27: 0.055 | H27: 0.055 | I27: 0.055 | J27: 0.055 | K27: 0.055 | L27: 0.055 | N27: Historical Median of Last 10 Years

Sheet Working Capital Schedule
B2: Working Capital Schedule
B4: Particulars | C4: 2017 | D4: =C4+1 | E4: =D4+1 | F4: =E4+1 | G4: =F4+1 | H4: =G4+1 | I4: =H4+1 | J4: =I4+1 | K4: =J4+1 | ... T4: =S4+1
B6: Revenue | C6: =PL!C6 | D6: =PL!D6 | E6: =PL!E6 | F6: =PL!F6 | G6: =PL!G6 | H6: =PL!H6 | I6: =PL!I6 | J6: =PL!J6 | ... T6: =PL!T6
B7: COGS | C7: =-PL!C7 | D7: =-PL!D7 | E7: =-PL!E7 | F7: =-PL!F7 | G7: =-PL!G7 | H7: =-PL!H7 | I7: =-PL!I7 | J7: =-PL!J7 | ... T7: =-PL!T7
B9: Accounts Receivables | C9: =BS!C42 | D9: =BS!D42 | E9: =BS!E42 | F9: =BS!F42 | G9: =BS!G42 | H9: =BS!H42 | I9: =BS!I42 | J9: =BS!J42 | ... L9: =BS!L42 | M9: =(2*(M6*Assumptions!E25)/365)-L9 | N9: =(2*(N6*Assumptions!F25)/365)-M9 | O9: =(2*(O6*Assumptions!G25)/365)-N9 | P9: =(2*(P6*Assumptions!H25)/365)-O9 | Q9: =(2*(Q6*Assumptions!I25)/365)-P9 | R9: =(2*(R6*Assumptions!J25)/365)-Q9 | S9: =(2*(S6*Assumptions!K25)/365)-R9 | T9: =(2*(T6*Assumptions!L25)/365)-S9
B10: Receivables Days | D10: =AVERAGE(C9:D9)/D6*365 | E10: =AVERAGE(D9:E9)/E6*365 | F10: =AVERAGE(E9:F9)/F6*365 | G10: =AVERAGE(F9:G9)/G6*365 | H10: =AVERAGE(G9:H9)/H6*365 | I10: =AVERAGE(H9:I9)/I6*365 | J10: =AVERAGE(I9:J9)/J6*365 | K10: =AVERAGE(J9:K9)/K6*365 | ... T10: =AVERAGE(S9:T9)/T6*365
B12: Inventory | C12: =BS!C43 | D12: =BS!D43 | E12: =BS!E43 | F12: =BS!F43 | G12: =BS!G43 | H12: =BS!H43 | I12: =BS!I43 | J12: =BS!J43 | ... L12: =BS!L43 | M12: =(2*(M7*Assumptions!E26)/365)-L12 | N12: =(2*(N7*Assumptions!F26)/365)-M12 | O12: =(2*(O7*Assumptions!G26)/365)-N12 | P12: =(2*(P7*Assumptions!H26)/365)-O12 | Q12: =(2*(Q7*Assumptions!I26)/365)-P12 | R12: =(2*(R7*Assumptions!J26)/365)-Q12 | S12: =(2*(S7*Assumptions!K26)/365)-R12 | T12: =(2*(T7*Assumptions!L26)/365)-S12
B13: Inventory Days | D13: =AVERAGE(C12:D12)/D7*365 | E13: =AVERAGE(D12:E12)/E7*365 | F13: =AVERAGE(E12:F12)/F7*365 | G13: =AVERAGE(F12:G12)/G7*365 | H13: =AVERAGE(G12:H12)/H7*365 | I13: =AVERAGE(H12:I12)/I7*365 | J13: =AVERAGE(I12:J12)/J7*365 | K13: =AVERAGE(J12:K12)/K7*365 | ... T13: =AVERAGE(S12:T12)/T7*365
B15: Trade Payables | C15: =BS!C21 | D15: =BS!D21 | E15: =BS!E21 | F15: =BS!F21 | G15: =BS!G21 | H15: =BS!H21 | I15: =BS!I21 | J15: =BS!J21 | ... L15: =BS!L21 | M15: =(2*(M7*Assumptions!E22)/365)-L15 | N15: =(2*(N7*Assumptions!F22)/365)-M15 | O15: =(2*(O7*Assumptions!G22)/365)-N15 | P15: =(2*(P7*Assumptions!H22)/365)-O15 | Q15: =(2*(Q7*Assumptions!I22)/365)-P15 | R15: =(2*(R7*Assumptions!J22)/365)-Q15 | S15: =(2*(S7*Assumptions!K22)/365)-R15 | T15: =(2*(T7*Assumptions!L22)/365)-S15
B16: Payable Days | D16: =AVERAGE(C15:D15)/D7*365 | E16: =AVERAGE(D15:E15)/E7*365 | F16: =AVERAGE(E15:F15)/F7*365 | G16: =AVERAGE(F15:G15)/G7*365 | H16: =AVERAGE(G15:H15)/H7*365 | I16: =AVERAGE(H15:I15)/I7*365 | J16: =AVERAGE(I15:J15)/J7*365 | K16: =AVERAGE(J15:K15)/K7*365 | ... T16: =AVERAGE(S15:T15)/T7*365
B18: Total Current Assets | C18: =BS!C42+BS!C43+BS!C44 | D18: =BS!D42+BS!D43+BS!D44 | E18: =BS!E42+BS!E43+BS!E44 | F18: =BS!F42+BS!F43+BS!F44 | G18: =BS!G42+BS!G43+BS!G44 | H18: =BS!H42+BS!H43+BS!H44 | I18: =BS!I42+BS!I43+BS!I44 | J18: =BS!J42+BS!J43+BS!J44 | ... T18: =BS!T42+BS!T43+BS!T44
B19: Total Current Liabilities | C19: =BS!C25 | D19: =BS!D25 | E19: =BS!E25 | F19: =BS!F25 | G19: =BS!G25 | H19: =BS!H25 | I19: =BS!I25 | J19: =BS!J25 | ... T19: =BS!T25
B20: WC | C20: =C18-C19 | D20: =D18-D19 | E20: =E18-E19 | F20: =F18-F19 | G20: =G18-G19 | H20: =H18-H19 | I20: =I18-I19 | J20: =J18-J19 | ... T20: =T18-T19
B21: Change In NWC | D21: =D20-C20 | E21: =E20-D20 | F21: =F20-E20 | G21: =G20-F20 | H21: =H20-G20 | I21: =I20-H20 | J21: =J20-I20 | K21: =K20-J20 | ... T21: =T20-S20

Sheet PL
B2: Income Statement
A4: x | B4: Particulars | C4: 2017 | D4: =C4+1 | E4: =D4+1 | F4: =E4+1 | G4: =F4+1 | H4: =G4+1 | I4: =H4+1 | J4: =I4+1 | K4: =J4+1 | ... T4: =S4+1
B6: Sales | C6: 8817.5 | D6: 8590.6 | E6: 9340.8 | F6: 9325.4 | G6: 8131.3 | H6: 9712.4 | I6: 10612 | J6: 11321 | K6: 12069 | L6: 12467 | M6: =L6*(1+Scenarios!H10) | N6: =M6*(1+Scenarios!I10) | O6: =N6*(1+Scenarios!J10) | P6: =O6*(1+Scenarios!K10) | Q6: =P6*(1+Scenarios!L10) | R6: =Q6*(1+Scenarios!M10) | S6: =R6*(1+Scenarios!N10) | T6: =S6*(1+Scenarios!O10)
B7: Total COGS | C7: -5151.3 | D7: -4557.3 | E7: -4966.4 | F7: -5370 | G7: -4807.5 | H7: -5680.9 | I7: -6503 | J7: -6542 | K7: -6860 | L7: -6674 | M7: =-M6*(1-Scenarios!H19) | N7: =-N6*(1-Scenarios!I19) | O7: =-O6*(1-Scenarios!J19) | P7: =-P6*(1-Scenarios!K19) | Q7: =-Q6*(1-Scenarios!L19) | R7: =-R6*(1-Scenarios!M19) | S7: =-S6*(1-Scenarios!N19) | T7: =-T6*(1-Scenarios!O19)
A8: x | B8: Gross Profit | C8: =C6+C7 | D8: =D6+D7 | E8: =E6+E7 | F8: =F6+F7 | G8: =G6+G7 | H8: =H6+H7 | I8: =I6+I7 | J8: =J6+J7 | ... T8: =T6+T7
B9: Operating Expenes
B10: Employee Cost | C10: -688.9 | D10: -681.2 | E10: -690.2 | F10: -530.4 | G10: -557 | H10: -653.9 | I10: -613 | J10: -549 | K10: -614 | L10: -635 | M10: =-M6*Assumptions!E7 | N10: =-N6*Assumptions!F7 | O10: =-O6*Assumptions!G7 | P10: =-P6*Assumptions!H7 | Q10: =-Q6*Assumptions!I7 | R10: =-R6*Assumptions!J7 | S10: =-S6*Assumptions!K7 | T10: =-T6*Assumptions!L7
B11: Selling and admin | C11: -1985.9 | D11: -2142.9 | E11: -2290.4 | F11: -1854 | G11: -1715.4 | H11: -1782.4 | I11: -2079 | J11: -2230 | K11: -2359 | L11: -2879 | M11: =-M6*Assumptions!E8 | N11: =-N6*Assumptions!F8 | O11: =-O6*Assumptions!G8 | P11: =-P6*Assumptions!H8 | Q11: =-Q6*Assumptions!I8 | R11: =-R6*Assumptions!J8 | S11: =-S6*Assumptions!K8 | T11: =-T6*Assumptions!L8
B12: Total Operating Expenses | C12: =SUM(C10:C11) | D12: =SUM(D10:D11) | E12: =SUM(E10:E11) | F12: =SUM(F10:F11) | G12: =SUM(G10:G11) | H12: =SUM(H10:H11) | I12: =SUM(I10:I11) | J12: =SUM(J10:J11) | ... T12: =SUM(T10:T11)
A13: x | B13: EBITDA | C13: =C8+C12 | D13: =D8+D12 | E13: =E8+E12 | F13: =F8+F12 | G13: =G8+G12 | H13: =H8+H12 | I13: =I8+I12 | J13: =J8+J12 | ... T13: =T8+T12
B14: Depreciation & Amortization | C14: -188.6 | D14: -192.3 | E14: -214.7 | F14: -285.3 | G14: -299.1 | H14: -303.8 | I14: -283 | J14: -275 | K14: -283 | L14: -289 | M14: ='Working Schedules'!H70 | N14: ='Working Schedules'!I70 | O14: ='Working Schedules'!J70 | P14: ='Working Schedules'!K70 | Q14: ='Working Schedules'!L70 | R14: ='Working Schedules'!M70 | S14: ='Working Schedules'!N70 | T14: ='Working Schedules'!O70
B15: EBIT | C15: =C13+C14 | D15: =D13+D14 | E15: =E13+E14 | F15: =F13+F14 | G15: =G13+G14 | H15: =H13+H14 | I15: =I13+I14 | J15: =J13+J14 | ... T15: =T13+T14
B16: Other Income(Inc Interest) | C16: 105.3 | D16: 218.9 | E16: 69.2 | F16: 22 | G16: 39.6 | H16: 35.5 | I16: 73.1 | J16: 225 | K16: 336 | L16: 478 | M16: 0 | N16: 0 | O16: 0 | P16: 0 | Q16: 0 | R16: 0 | S16: 0 | T16: 0
B17: Exceptional Items | C17: ='P&L'!C22 | D17: -44.5 | E17: 2.6 | F17: 66.6 | G17: -64.3 | H17: -165.2 | I17: 176.4 | J17: -17 | K17: -65 | L17: 38 | M17: 0 | N17: 0 | O17: 0 | P17: 0 | Q17: 0 | R17: 0 | S17: 0 | T17: 0
B18: Interest Paid | C18: -375.1 | D18: -277.5 | E18: -237.2 | F18: -212 | G18: -187.6 | H18: -88 | I18: -104 | J18: -76 | K18: -89 | L18: -158 | M18: =-'Working Schedules'!H33 | N18: =-'Working Schedules'!I33 | O18: =-'Working Schedules'!J33 | P18: =-'Working Schedules'!K33 | Q18: =-'Working Schedules'!L33 | R18: =-'Working Schedules'!M33 | S18: =-'Working Schedules'!N33 | T18: =-'Working Schedules'!O33
B19: Interest Received | M19: =BS!L45*Assumptions!E9 | N19: =BS!M45*Assumptions!F9 | O19: =BS!N45*Assumptions!G9 | P19: =BS!O45*Assumptions!H9 | Q19: =BS!P45*Assumptions!I9 | R19: =BS!Q45*Assumptions!J9 | S19: =BS!R45*Assumptions!K9 | T19: =BS!S45*Assumptions!L9
A20: x | B20: Profit Before Tax (PBT) | C20: =SUM(C15:C18) | D20: =SUM(D15:D18) | E20: =SUM(E15:E19) | F20: =SUM(F15:F19) | G20: =SUM(G15:G19) | H20: =SUM(H15:H19) | I20: =SUM(I15:I19) | J20: =SUM(J15:J19) | K20: =SUM(K15:K19) | L20: =SUM(L15:L19) | ... T20: =SUM(T15:T19)
B21: Tax | C21: -69.7 | D21: -259.9 | E21: -328.1 | F21: -539.7 | G21: -177.9 | H21: -276 | I21: -153 | J21: -449 | K21: -553 | L21: -510 | M21: =-M20*Assumptions!E10 | N21: =-N20*Assumptions!F10 | O21: =-O20*Assumptions!G10 | P21: =-P20*Assumptions!H10 | Q21: =-Q20*Assumptions!I10 | R21: =-R20*Assumptions!J10 | S21: =-S20*Assumptions!K10 | T21: =-T20*Assumptions!L10
B22: Adjustments | C22: -2.2 | D22: -2 | E22: -2 | F22: -2 | G22: 0 | H22: 12.9 | I22: -0.7 | J22: 0 | K22: 0 | L22: 0 | M22: 0 | N22: 0 | O22: 0 | P22: 0 | Q22: 0 | R22: 0 | S22: 0 | T22: 0
A23: x | B23: Profit After Tax (PAT) | C23: =SUM(C20:C22) | D23: =SUM(D20:D22) | E23: =SUM(E20:E22) | F23: =SUM(F20:F22) | G23: =SUM(G20:G22) | H23: =SUM(H20:H22) | I23: =SUM(I20:I22) | J23: =SUM(J20:J22) | ... L23: =SUM(L20:L22) | M23: =M20+M21 | N23: =N20+N21 | O23: =O20+O21 | P23: =P20+P21 | Q23: =Q20+Q21 | R23: =R20+R21 | S23: =S20+S21 | T23: =T20+T21

Sheet BS
B2: Balance Sheet
B4: Particulars | C4: 2017 | D4: =C4+1 | E4: =D4+1 | F4: =E4+1 | G4: =F4+1 | H4: =G4+1 | I4: =H4+1 | J4: =I4+1 | K4: =J4+1 | ... T4: =S4+1
A6: x | B6: Equities & Liablilities
B7: Shareholders' Fund
B8: Share Capital | C8: 145.3 | D8: 145.3 | E8: 145.3 | F8: 145.3 | G8: 145.3 | H8: 145.3 | I8: 145.5 | J8: 145 | K8: 145 | L8: 145 | M8: =L8 | N8: =M8 | O8: =N8 | P8: =O8 | Q8: =P8 | R8: =Q8 | S8: =R8 | T8: =S8
B9: Reserve & Surplus | C9: 1640.3 | D9: 2273.8 | E9: 2945 | F9: 3582.7 | G9: 3974.5 | H9: 4808.4 | I9: 5854 | J9: 6976 | K9: 7959 | L9: 8808 | M9: =L9+M10+M11 | N9: =M9+N10+N11 | O9: =N9+O10+O11 | P9: =O9+P10+P11 | Q9: =P9+Q10+Q11 | R9: =Q9+R10+R11 | S9: =R9+S10+S11 | T9: =S9+T10+T11
B10: PAT | M10: =PL!M23 | N10: =PL!N23 | O10: =PL!O23 | P10: =PL!P23 | Q10: =PL!Q23 | R10: =PL!R23 | S10: =PL!S23 | T10: =PL!T23
B11: Dividend Payout | M11: =-M10*Assumptions!E11 | N11: =-N10*Assumptions!F11 | O11: =-O10*Assumptions!G11 | P11: =-P10*Assumptions!H11 | Q11: =-Q10*Assumptions!I11 | R11: =-R10*Assumptions!J11 | S11: =-S10*Assumptions!K11 | T11: =-T10*Assumptions!L11
B12: Total Shareholders' Fund | C12: =SUM(C8:C9) | D12: =SUM(D8:D9) | E12: =SUM(E8:E9) | F12: =SUM(F8:F9) | G12: =SUM(G8:G9) | H12: =SUM(H8:H9) | I12: =SUM(I8:I9) | J12: =SUM(J8:J9) | ... T12: =SUM(T8:T9)
A14: x | B14: Non-Current Liabilities
B15: Long Term Borrowings | C15: 869.7 | D15: 762.8 | E15: 780.4 | F15: 14.7 | G15: 2.2 | H15: 0.9 | I15: 0.3 | J15: 0 | K15: 0 | L15: 0 | M15: =L15 | N15: =M15 | O15: =N15 | P15: =O15 | Q15: =P15 | R15: =Q15 | S15: =R15 | T15: =S15
B16: Deferred Tax Liabilities [Net] | C16: 0 | D16: 0 | E16: 0 | F16: 7.6 | G16: 26.1 | H16: 48.3 | I16: 45.1 | J16: 73 | K16: 72 | L16: 18 | M16: =L16 | N16: =M16 | O16: =N16 | P16: =O16 | Q16: =P16 | R16: =Q16 | S16: =R16 | T16: =S16
B17: Lease Liabilities | C17: 13.5 | D17: 7 | E17: 23.9 | F17: 196.5 | G17: 157.8 | H17: 263.9 | I17: 182.4 | J17: 240.4 | K17: 480 | L17: 407 | M17: ='Working Schedules'!H22 | N17: ='Working Schedules'!I22 | O17: ='Working Schedules'!J22 | P17: ='Working Schedules'!K22 | Q17: ='Working Schedules'!L22 | R17: ='Working Schedules'!M22 | S17: ='Working Schedules'!N22 | T17: ='Working Schedules'!O22
B18: Total Non-Current Liabilities | C18: =SUM(C15:C17) | D18: =SUM(D15:D17) | E18: =SUM(E15:E17) | F18: =SUM(F15:F17) | G18: =SUM(G15:G17) | H18: =SUM(H15:H17) | I18: =SUM(I15:I17) | J18: =SUM(J15:J17) | ... T18: =SUM(T15:T17)
A20: x | B20: Current Liabilities
B21: Trade Payables | C21: 1224.7 | D21: 1455.1 | E21: 1408.3 | F21: 1199.4 | G21: 1417.2 | H21: 1582.1 | I21: 1782.5 | J21: 1954 | K21: 2239 | L21: 2383 | M21: ='Working Capital Schedule'!M15 | N21: ='Working Capital Schedule'!N15 | O21: ='Working Capital Schedule'!O15 | P21: ='Working Capital Schedule'!P15 | Q21: ='Working Capital Schedule'!Q15 | R21: ='Working Capital Schedule'!R15 | S21: ='Working Capital Schedule'!S15 | T21: ='Working Capital Schedule'!T15
B22: Short Term Borrowings | C22: 2906.9 | D22: 2301.3 | E22: 2089.4 | F22: 1606 | G22: 874.5 | H22: 340.8 | I22: 0.8 | J22: 25 | K22: 0 | L22: 6 | M22: =L22 | N22: =M22 | O22: =N22 | P22: =O22 | Q22: =P22 | R22: =Q22 | S22: =R22 | T22: =S22
B23: ST Provisions | C23: 319.4 | D23: 361.9 | E23: 399.2 | F23: 462.1 | G23: 583.4 | H23: 502.9 | I23: 385.4 | J23: 383 | K23: 391 | L23: 541 | M23: =Assumptions!E23*PL!M6 | N23: =Assumptions!F23*PL!N6 | O23: =Assumptions!G23*PL!O6 | P23: =Assumptions!H23*PL!P6 | Q23: =Assumptions!I23*PL!Q6 | R23: =Assumptions!J23*PL!R6 | S23: =Assumptions!K23*PL!S6 | T23: =Assumptions!L23*PL!T6
B24: Other Current Liabilities | C24: 1776.1 | D24: 1649.1 | E24: 1317.4 | F24: 1637 | G24: 1356 | H24: 1218.7 | I24: 1365.5 | J24: 1452.6 | K24: 1962 | L24: 2161 | M24: =Assumptions!E24*PL!M6 | N24: =Assumptions!F24*PL!N6 | O24: =Assumptions!G24*PL!O6 | P24: =Assumptions!H24*PL!P6 | Q24: =Assumptions!I24*PL!Q6 | R24: =Assumptions!J24*PL!R6 | S24: =Assumptions!K24*PL!S6 | T24: =Assumptions!L24*PL!T6
B25: Total Current Liabilities | C25: =SUM(C21:C24) | D25: =SUM(D21:D24) | E25: =SUM(E21:E24) | F25: =SUM(F21:F24) | G25: =SUM(G21:G24) | H25: =SUM(H21:H24) | I25: =SUM(I21:I24) | J25: =SUM(J21:J24) | ... T25: =SUM(T21:T24)
A27: x | B27: Total Equity & Liabilities | C27: =C12+C18+C25 | D27: =D12+D18+D25 | E27: =E12+E18+E25 | F27: =F12+F18+F25 | G27: =G12+G18+G25 | H27: =H12+H18+H25 | I27: =I12+I18+I25 | J27: =J12+J18+J25 | ... T27: =T12+T18+T25
B29: Assets
B30: Non-Current Assets
B31: Fixed Assets
B32: Property Plant & Equip | C32: 1455.4 | D32: 1418.2 | E32: 1371.4 | F32: 1353.8 | G32: 1324.7 | H32: 1215.2 | I32: 978.3 | J32: 844 | K32: 850 | L32: 1215 | M32: ='Working Schedules'!H67 | N32: ='Working Schedules'!I67 | O32: ='Working Schedules'!J67 | P32: ='Working Schedules'!K67 | Q32: ='Working Schedules'!L67 | R32: ='Working Schedules'!M67 | S32: ='Working Schedules'!N67 | T32: ='Working Schedules'!O67
B33: Capital Work in Progress | C33: 199.3 | D33: 101.8 | E33: 101.9 | F33: 104.1 | G33: 88.3 | H33: 87.7 | I33: 66.8 | J33: 37 | K33: 72 | L33: 77 | M33: ='Working Schedules'!H44 | N33: ='Working Schedules'!I44 | O33: ='Working Schedules'!J44 | P33: ='Working Schedules'!K44 | Q33: ='Working Schedules'!L44 | R33: ='Working Schedules'!M44 | S33: ='Working Schedules'!N44 | T33: ='Working Schedules'!O44
B34: ROU Assets | F34: 197.5 | G34: 164.4 | H34: 260.6 | I34: 172.6 | J34: 226.6 | K34: 456.6 | L34: 500.49 | M34: ='Working Schedules'!H55 | N34: ='Working Schedules'!I55 | O34: ='Working Schedules'!J55 | P34: ='Working Schedules'!K55 | Q34: ='Working Schedules'!L55 | R34: ='Working Schedules'!M55 | S34: ='Working Schedules'!N55 | T34: ='Working Schedules'!O55
B35: Intangible Assets | C35: 393.2 | D35: 383.8 | E35: 373.7 | F35: 383.6 | G35: 375.5 | H35: 358 | I35: 356.7 | J35: 349 | K35: 329 | L35: 76 | M35: ='Working Schedules'!H81 | N35: ='Working Schedules'!I81 | O35: ='Working Schedules'!J81 | P35: ='Working Schedules'!K81 | Q35: ='Working Schedules'!L81 | R35: ='Working Schedules'!M81 | S35: ='Working Schedules'!N81 | T35: ='Working Schedules'!O81
B36: Goodwill | C36: 68 | D36: 36.1 | E36: 49.3 | F36: 21 | G36: 21 | H36: 21 | I36: 1 | J36: 1 | K36: 1 | L36: 55 | M36: =L36 | N36: =M36 | O36: =N36 | P36: =O36 | Q36: =P36 | R36: =Q36 | S36: =R36 | T36: =S36
B37: Total Fixed Assets | C37: =SUM(C32:C36) | D37: =SUM(D32:D36) | E37: =SUM(E32:E36) | F37: =SUM(F32:F36) | G37: =SUM(G32:G36) | H37: =SUM(H32:H36) | I37: =SUM(I32:I36) | J37: =SUM(J32:J36) | ... T37: =SUM(T32:T36)
B38: Other Non Current Assets | C38: 1030.9 | D38: 1280.2 | E38: 1948.8 | F38: 1921 | G38: 1760.1 | H38: 1805.4 | I38: 1951.5 | J38: 2414.4 | K38: 2337.4 | L38: 1982.51 | M38: 2009.9114 | N38: 2009.9114 | O38: 2009.9114 | P38: 2009.9114 | Q38: 2009.9114 | R38: 2009.9114 | S38: 2009.9114 | T38: 2009.9114
B39: Total Non Current Assets | C39: =SUM(C37:C38) | D39: =SUM(D37:D38) | E39: =SUM(E37:E38) | F39: =SUM(F37:F38) | G39: =SUM(G37:G38) | H39: =SUM(H37:H38) | I39: =SUM(I37:I38) | J39: =SUM(J37:J38) | ... T39: =SUM(T37:T38)
B41: Current Assets
B42: Accounts Receivables | C42: 2953.4 | D42: 2711.2 | E42: 2542.5 | F42: 2283.5 | G42: 2187.2 | H42: 2373.6 | I42: 2434 | J42: 3056 | K42: 3410 | L42: 3609 | M42: ='Working Capital Schedule'!M9 | N42: ='Working Capital Schedule'!N9 | O42: ='Working Capital Schedule'!O9 | P42: ='Working Capital Schedule'!P9 | Q42: ='Working Capital Schedule'!Q9 | R42: ='Working Capital Schedule'!R9 | S42: ='Working Capital Schedule'!S9 | T42: ='Working Capital Schedule'!T9
B43: Inventories | C43: 1927.6 | D43: 1919.7 | E43: 1934.3 | F43: 1927.5 | G43: 2051.9 | H43: 2156.7 | I43: 2230 | J43: 2063 | K43: 2305 | L43: 2668 | M43: ='Working Capital Schedule'!M12 | N43: ='Working Capital Schedule'!N12 | O43: ='Working Capital Schedule'!O12 | P43: ='Working Capital Schedule'!P12 | Q43: ='Working Capital Schedule'!Q12 | R43: ='Working Capital Schedule'!R12 | S43: ='Working Capital Schedule'!S12 | T43: ='Working Capital Schedule'!T12
B44: Other Current Assets | C44: 780.8 | D44: 849.2 | E44: 504.1 | F44: 585.8 | G44: 480 | H44: 350.7 | I44: 431.5 | J44: 390 | K44: 584 | L44: 1152 | M44: =L44*(1+Assumptions!E27) | N44: =M44*(1+Assumptions!F27) | O44: =N44*(1+Assumptions!G27) | P44: =O44*(1+Assumptions!H27) | Q44: =P44*(1+Assumptions!I27) | R44: =Q44*(1+Assumptions!J27) | S44: =R44*(1+Assumptions!K27) | T44: =S44*(1+Assumptions!L27)
B45: Cash Balance(Incl. Bank and Current Investments) | C45: 87.3 | D45: 256.1 | E45: 282.9 | F45: 73.5 | G45: 83.9 | H45: 282.4 | I45: 1139.1 | J45: 1868 | K45: 2903 | L45: 3134 | M45: =CS!M22 | N45: =CS!N22 | O45: =CS!O22 | P45: =CS!P22 | Q45: =CS!Q22 | R45: =CS!R22 | S45: =CS!S22 | T45: =CS!T22
B46: Total Current Assets | C46: =SUM(C42:C45) | D46: =SUM(D42:D45) | E46: =SUM(E42:E45) | F46: =SUM(F42:F45) | G46: =SUM(G42:G45) | H46: =SUM(H42:H45) | I46: =SUM(I42:I45) | J46: =SUM(J42:J45) | ... T46: =SUM(T42:T45)
B48: Total Assets | C48: =C39+C46 | D48: =D39+D46 | E48: =E39+E46 | F48: =F39+F46 | G48: =G39+G46 | H48: =H39+H46 | I48: =I39+I46 | J48: =J39+J46 | ... T48: =T39+T46
B51: Test | C51: =C48-C27 | D51: =D48-D27 | E51: =E48-E27 | F51: =F48-F27 | G51: =G48-G27 | H51: =H48-H27 | I51: =I48-I27 | J51: =J48-J27 | ... T51: =T48-T27

Sheet CS
B2: Cash Flow Statement
B4: Particulars | C4: 2017 | D4: =C4+1 | E4: =D4+1 | F4: =E4+1 | G4: =F4+1 | H4: =G4+1 | I4: =H4+1 | J4: =I4+1 | K4: =J4+1 | ... T4: =S4+1
A6: x | B6: Net Profit Aafter Tax (PAT) | C6: =PL!C23 | D6: =PL!D23 | E6: =PL!E23 | F6: =PL!F23 | G6: =PL!G23 | H6: =PL!H23 | I6: =PL!I23 | J6: =PL!J23 | ... T6: =PL!T23
B7: D&A | C7: =-PL!C14 | D7: =-PL!D14 | E7: =-PL!E14 | F7: =-PL!F14 | G7: =-PL!G14 | H7: =-PL!H14 | I7: =-PL!I14 | J7: =-PL!J14 | ... T7: =-PL!T14
B8: +/- in other non cash items | C8: 227.2 | D8: 358.9 | E8: 103.9 | F8: 3 | G8: 1752.2 | H8: 611.5 | I8: -468.8 | J8: -431.9 | K8: 94.6 | L8: -37 | M8: =-PL!M19-PL!M18 | N8: =-PL!N19-PL!N18 | O8: =-PL!O19-PL!O18 | P8: =-PL!P19-PL!P18 | Q8: =-PL!Q19-PL!Q18 | R8: =-PL!R19-PL!R18 | S8: =-PL!S19-PL!S18 | T8: =-PL!T19-PL!T18
B9: +/- change in NWC | C9: 138 | D9: =-'Working Capital Schedule'!D21 | E9: =-'Working Capital Schedule'!E21 | F9: =-'Working Capital Schedule'!F21 | G9: =-'Working Capital Schedule'!G21 | H9: =-'Working Capital Schedule'!H21 | I9: =-'Working Capital Schedule'!I21 | J9: =-'Working Capital Schedule'!J21 | K9: =-'Working Capital Schedule'!K21 | ... T9: =-'Working Capital Schedule'!T21
A10: x | B10: Cash flow from Operating Activities | C10: =SUM(C6:C9) | D10: =SUM(D6:D9) | E10: =SUM(E6:E9) | F10: =SUM(F6:F9) | G10: =SUM(G6:G9) | H10: =SUM(H6:H9) | I10: =SUM(I6:I9) | J10: =SUM(J6:J9) | ... T10: =SUM(T6:T9)
B11: Interest Received | C11: 19.7 | D11: 4.2 | E11: 6.4 | F11: 6.2 | G11: 11.1 | H11: 6.4 | I11: 20.4 | J11: 42 | K11: 36 | L11: 67 | M11: =M21*Assumptions!E9 | N11: =N21*Assumptions!F9 | O11: =O21*Assumptions!G9 | P11: =P21*Assumptions!H9 | Q11: =Q21*Assumptions!I9 | R11: =R21*Assumptions!J9 | S11: =S21*Assumptions!K9 | T11: =T21*Assumptions!L9
B12: Capex | C12: -311 | D12: -184.3 | E12: -173 | F12: -211.6 | G12: -158.9 | H12: -134 | I12: -136.6 | J12: -98 | K12: -162 | L12: -181 | M12: =-'Working Schedules'!H42 | N12: =-'Working Schedules'!I42 | O12: =-'Working Schedules'!J42 | P12: =-'Working Schedules'!K42 | Q12: =-'Working Schedules'!L42 | R12: =-'Working Schedules'!M42 | S12: =-'Working Schedules'!N42 | T12: =-'Working Schedules'!O42
B13: Others | C13: 64 | D13: 284 | E13: 128 | F13: 12 | G13: 35 | H13: -176 | I13: 12 | J13: -262 | K13: -227 | L13: 75 | M13: 0 | N13: 0 | O13: 0 | P13: 0 | Q13: 0 | R13: 0 | S13: 0 | T13: 0
B14: Cash flow from investing activities | C14: =SUM(C11:C13) | D14: =SUM(D11:D13) | E14: =SUM(E11:E13) | F14: =SUM(F11:F13) | G14: =SUM(G11:G13) | H14: =SUM(H11:H13) | I14: =SUM(I11:I13) | J14: =SUM(J11:J13) | ... T14: =SUM(T11:T13)
B15: Repayment Lease Liabilities | C15: -8.6 | D15: 0 | E15: 0 | F15: -64.5 | G15: -80.7 | H15: -100.2 | I15: -124 | J15: -126 | K15: -137 | L15: -144 | M15: ='Working Schedules'!H9 | N15: ='Working Schedules'!I9 | O15: ='Working Schedules'!J9 | P15: ='Working Schedules'!K9 | Q15: ='Working Schedules'!L9 | R15: ='Working Schedules'!M9 | S15: ='Working Schedules'!N9 | T15: ='Working Schedules'!O9
B16: Interest Paid | C16: -375.2 | D16: -252.8 | E16: -229.3 | F16: -181.1 | G16: -142 | H16: -50.1 | I16: -36.3 | J16: -21 | K16: -40 | L16: -37 | M16: =PL!M18 | N16: =PL!N18 | O16: =PL!O18 | P16: =PL!P18 | Q16: =PL!Q18 | R16: =PL!R18 | S16: =PL!S18 | T16: =PL!T18
B17: Dividend Paid | C17: 0 | D17: 0 | E17: 0 | F17: 0 | G17: 0 | H17: 0 | I17: 0 | J17: -284 | K17: -355 | L17: -1263 | M17: =-Assumptions!E11*PL!M23 | N17: =-Assumptions!F11*PL!N23 | O17: =-Assumptions!G11*PL!O23 | P17: =-Assumptions!H11*PL!P23 | Q17: =-Assumptions!I11*PL!Q23 | R17: =-Assumptions!J11*PL!R23 | S17: =-Assumptions!K11*PL!S23 | T17: =-Assumptions!L11*PL!T23
B18: Others | C18: -86.4 | D18: -607.4 | E18: -653.6 | F18: -553.6 | G18: -1471.8 | H18: -324.9 | I18: 505.9 | J18: 359.9 | K18: -27 | L18: 255 | M18: 0 | N18: 0 | O18: 0 | P18: 0 | Q18: 0 | R18: 0 | S18: 0 | T18: 0
B19: Cash flow from Financing activities | C19: =SUM(C15:C18) | D19: =SUM(D15:D18) | E19: =SUM(E15:E18) | F19: =SUM(F15:F18) | G19: =SUM(G15:G18) | H19: =SUM(H15:H18) | I19: =SUM(I15:I18) | J19: =SUM(J15:J18) | ... T19: =SUM(T15:T18)
A20: x | B20: Net change in Cash | C20: =C10+C14+C19 | D20: =D10+D14+D19 | E20: =E10+E14+E19 | F20: =F10+F14+F19 | G20: =G10+G14+G19 | H20: =H10+H14+H19 | I20: =I10+I14+I19 | J20: =J10+J14+J19 | ... T20: =T10+T14+T19
B21: Opening Cash Balance | C21: 138 | D21: =C22 | E21: =D22 | F21: =E22 | G21: =F22 | H21: =G22 | I21: =H22 | J21: =I22 | K21: =J22 | ... T21: =S22
A22: x | B22: Closing Cash Balance | C22: =C20+C21 | D22: =D20+D21 | E22: =E20+E21 | F22: =F20+F21 | G22: =G20+G21 | H22: =H20+H21 | I22: =I20+I21 | J22: =J20+J21 | ... T22: =T20+T21

Sheet Working Schedules
B2: Working Schedules
B4: Debt Schedule - Lease Liabilities
B5: Particulars | C5: 2022 | D5: =C5+1 | E5: =D5+1 | F5: =E5+1 | G5: =F5+1 | H5: =G5+1 | I5: =H5+1 | J5: =I5+1 | K5: =J5+1 | ... O5: =N5+1
B7: Opening Lease Liability | C7: =BS!G17 | D7: =C10 | E7: =D10 | F7: =E10 | G7: =F10 | H7: =G10 | I7: =H10 | J7: =I10 | K7: =J10 | ... O7: =N10
B8: Additions: New Leases | C8: 206.1 | D8: 42.5 | E8: =E52 | F8: 377 | G8: 71.6 | H8: =H52 | I8: =I52 | J8: =J52 | K8: =K52 | L8: =L52 | M8: =M52 | N8: =N52 | O8: =O52
B9: Less: Principal Repayment | C9: -100 | D9: -124 | E9: -126 | F9: -137 | G9: -144 | H9: =(1+Assumptions!E18)*G9 | I9: =(1+Assumptions!F18)*H9 | J9: =(1+Assumptions!G18)*I9 | K9: =(1+Assumptions!H18)*J9 | L9: =(1+Assumptions!I18)*K9 | M9: =(1+Assumptions!J18)*L9 | N9: =(1+Assumptions!K18)*M9 | O9: =(1+Assumptions!L18)*N9
B10: Closing Lease Liability | C10: =SUM(C7:C9) | D10: =SUM(D7:D9) | E10: =SUM(E7:E9) | F10: =SUM(F7:F9) | G10: =SUM(G7:G9) | H10: =SUM(H7:H9) | I10: =SUM(I7:I9) | J10: =SUM(J7:J9) | ... O10: =SUM(O7:O9)
B11: Interest | C11: 11.9 | D11: 16 | E11: 21 | F11: 40 | G11: 37 | H11: =AVERAGE(H10,H7)*Assumptions!E19 | I11: =AVERAGE(I10,I7)*Assumptions!F19 | J11: =AVERAGE(J10,J7)*Assumptions!G19 | K11: =AVERAGE(K10,K7)*Assumptions!H19 | L11: =AVERAGE(L10,L7)*Assumptions!I19 | M11: =AVERAGE(M10,M7)*Assumptions!J19 | N11: =AVERAGE(N10,N7)*Assumptions!K19 | O11: =AVERAGE(O10,O7)*Assumptions!L19
B14: Debt Schedule - Working Capital loans/Others
B15: Particulars | C15: 2022 | D15: =C15+1 | E15: =D15+1 | F15: =E15+1 | G15: =F15+1 | H15: =G15+1 | I15: =H15+1 | J15: =I15+1 | K15: =J15+1 | ... O15: =N15+1
B17: Opening | C17: 876 | D17: =C19 | E17: =D19 | F17: =E19 | G17: =F19 | H17: =G19 | I17: =H19 | J17: =I19 | K17: =J19 | ... O17: =N19
B18: (Repayment)/Net proceeds | C18: -535 | D18: -341 | E18: 25 | F18: -25 | G18: 0 | H18: 0 | I18: 0 | J18: 0 | K18: 0 | L18: 0 | M18: 0 | N18: 0 | O18: 0
B19: Closing | C19: =SUM(C17:C18) | D19: =SUM(D17:D18) | E19: =SUM(E17:E18) | F19: =SUM(F17:F18) | G19: =SUM(G17:G18) | H19: =SUM(H17:H18) | I19: =SUM(I17:I18) | J19: =SUM(J17:J18) | ... O19: =SUM(O17:O18)
B20: Interest | C20: 38 | D20: 20.3 | E20: 0 | F20: 0 | G20: 0 | H20: 0 | I20: 0 | J20: 0 | K20: 0 | L20: 0 | M20: 0 | N20: 0 | O20: 0
B22: Total Debt | C22: =C19+C10 | D22: =D19+D10 | E22: =E19+E10 | F22: =F19+F10 | G22: =G19+G10 | H22: =H19+H10 | I22: =I19+I10 | J22: =J19+J10 | ... O22: =O19+O10
B27: Finance cost Schedule
B28: Particulars | C28: 2022 | D28: =C28+1 | E28: =D28+1 | F28: =E28+1 | G28: =F28+1 | H28: =G28+1 | I28: =H28+1 | J28: =I28+1 | K28: =J28+1 | ... O28: =N28+1
B30: Interest on lease liabilities | C30: =C11 | D30: =D11 | E30: =E11 | F30: =F11 | G30: =G11 | H30: =H11 | I30: =I11 | J30: =J11 | ... O30: =O11
B31: Interest on Borrowings | C31: =C20 | D31: =D20 | E31: =E20 | F31: =F20 | G31: =G20 | H31: =H20 | I31: =I20 | J31: =J20 | ... O31: =O20
B32: Interest Others | C32: 38.1 | D32: 67.6 | E32: 55 | F32: 49 | G32: 121 | H32: =Assumptions!E21 | I32: =Assumptions!F21 | J32: =Assumptions!G21 | K32: =Assumptions!H21 | L32: =Assumptions!I21 | M32: =Assumptions!J21 | N32: =Assumptions!K21 | O32: =Assumptions!L21
B33: Total | C33: =SUM(C30:C32) | D33: =SUM(D30:D32) | E33: =SUM(E30:E32) | F33: =SUM(F30:F32) | G33: =SUM(G30:G32) | H33: =SUM(H30:H32) | I33: =SUM(I30:I32) | J33: =SUM(J30:J32) | ... O33: =SUM(O30:O32)
B37: CWIP Schedule
B38: Particulars | C38: 2022 | D38: =C38+1 | E38: =D38+1 | F38: =E38+1 | G38: =F38+1 | H38: =G38+1 | I38: =H38+1 | J38: =I38+1 | K38: =J38+1 | ... O38: =N38+1
B40: Revenue | C40: =PL!C6 | D40: =PL!D6 | E40: =PL!E6 | F40: =PL!F6 | G40: =PL!G6 | H40: =PL!H6 | I40: =PL!I6 | J40: =PL!J6 | ... O40: =PL!O6
B41: Opening | C41: 88.3 | D41: =C44 | E41: =D44 | F41: =E44 | G41: =F44 | H41: =G44 | I41: =H44 | J41: =I44 | K41: =J44 | ... O41: =N44
B42: Additions(Capex) | C42: 123.4 | D42: 114.3 | E42: 96 | F42: 161 | G42: 181 | H42: =H40*Assumptions!E12 | I42: =I40*Assumptions!F12 | J42: =J40*Assumptions!G12 | K42: =K40*Assumptions!H12 | L42: =L40*Assumptions!I12 | M42: =M40*Assumptions!J12 | N42: =N40*Assumptions!K12 | O42: =O40*Assumptions!L12
B43: Capitalised | C43: -124 | D43: -135.2 | E43: -126 | F43: -126 | G43: -175.8 | H43: =-H42 | I43: =-I42 | J43: =-J42 | K43: =-K42 | L43: =-L42 | M43: =-M42 | N43: =-N42 | O43: =-O42
B44: Closing | C44: =SUM(C41:C43) | D44: =SUM(D41:D43) | E44: =SUM(E41:E43) | F44: =SUM(F41:F43) | G44: =SUM(G41:G43) | H44: =SUM(H41:H43) | I44: =SUM(I41:I43) | J44: =SUM(J41:J43) | ... O44: =SUM(O41:O43)
S47: 2026
B48: Right of Use of Assets Schedule | S48: Depreciation | T48: 289
B49: Particulars | C49: 2022 | D49: =C49+1 | E49: =D49+1 | F49: =E49+1 | G49: =F49+1 | H49: =G49+1 | I49: =H49+1 | J49: =I49+1 | K49: =J49+1 | ... O49: =N49+1 | S49: Payments of lease liabilities | T49: 144
S50: Interest paid | T50: 37
B51: Opening ROU assets | C51: 164.4 | D51: =C55 | E51: =D55 | F51: =E55 | G51: =F55 | H51: =G55 | I51: =H55 | J51: =I55 | K51: =J55 | ... O51: =N55 | S51: Finance costs (P&L) | T51: 158
B52: Additions | C52: 229.2 | D52: 85.8 | E52: 184 | F52: 394 | G52: =G40*0.022 | H52: =Assumptions!E15*H40 | I52: =Assumptions!F15*I40 | J52: =Assumptions!G15*J40 | K52: =Assumptions!H15*K40 | L52: =Assumptions!I15*L40 | M52: =Assumptions!J15*M40 | N52: =Assumptions!K15*N40 | O52: =Assumptions!L15*O40
B53: Depreciation | C53: -109.9 | D53: -130.1 | E53: -129 | F53: -147 | G53: -135 | H53: =H107 | I53: =I107 | J53: =J107 | K53: =K107 | L53: =L107 | M53: =M107 | N53: =N107 | O53: =O107
B54: Termination/Transfer | C54: -23.1 | D54: -43.7 | E54: -1 | F54: -17
B55: Closing ROU assets | C55: =SUM(C51:C54) | D55: =SUM(D51:D54) | E55: =SUM(E51:E54) | F55: =SUM(F51:F54) | G55: =SUM(G51:G54) | H55: =SUM(H51:H54) | I55: =SUM(I51:I54) | J55: =SUM(J51:J54) | ... O55: =SUM(O51:O54)
B59: Property Plant & Equipment Schedule
B60: Particulars | C60: 2022 | D60: =C60+1 | E60: =D60+1 | F60: =E60+1 | G60: =F60+1 | H60: =G60+1 | I60: =H60+1 | J60: =I60+1 | K60: =J60+1 | ... O60: =N60+1
B62: Gross PPE Opening | C62: 2247 | D62: =C65 | E62: =D65 | F62: =E65 | G62: =F65 | H62: =G65 | I62: =H65 | J62: =I65 | K62: =J65 | ... O62: =N65
...

Sheet DCF
B2: DCF Valuation | K2: WACC Calculation
B4: Particulars | C4: 2027 | D4: =C4+1 | E4: =D4+1 | F4: =E4+1 | G4: =F4+1 | H4: =G4+1 | I4: =H4+1 | J4: =I4+1 | K4: Risk Free Rate | N4: 0.07 | O4: (10-yr G-Sec)
K5: Rm | N5: 0.11 | O5: Nifty50 5 Year Monthly Return
B6: EBIT | C6: =PL!M15 | D6: =PL!N15 | E6: =PL!O15 | F6: =PL!P15 | G6: =PL!Q15 | H6: =PL!R15 | I6: =PL!S15 | J6: =PL!T15 | K6: Market Risk Premium | N6: 0.04 | O6: Rm-Rf
B7: Tax | C7: =Assumptions!E10 | D7: =Assumptions!F10 | E7: =Assumptions!G10 | F7: =Assumptions!H10 | G7: =Assumptions!I10 | H7: =Assumptions!J10 | I7: =Assumptions!K10 | J7: =Assumptions!L10 | K7: Beta | N7: ='Beta Calculation'!C7 | O7: Rf​+β×ERP
B8: NOPAT | C8: =C6*(1-C7) | D8: =D6*(1-D7) | E8: =E6*(1-E7) | F8: =F6*(1-F7) | G8: =G6*(1-G7) | H8: =H6*(1-H7) | I8: =I6*(1-I7) | J8: =J6*(1-J7) | K8: CAPM | N8: =N4+N7*N6
B9: Dep & Amor. | C9: =-PL!M14 | D9: =-PL!N14 | E9: =-PL!O14 | F9: =-PL!P14 | G9: =-PL!Q14 | H9: =-PL!R14 | I9: =-PL!S14 | J9: =-PL!T14 | K9: WACC | N9: =N8 | O9: Debt is almost negligible, therefore no impact on WACC
B10: Capex | C10: =-'Working Schedules'!H42 | D10: =-'Working Schedules'!I42 | E10: =-'Working Schedules'!J42 | F10: =-'Working Schedules'!K42 | G10: =-'Working Schedules'!L42 | H10: =-'Working Schedules'!M42 | I10: =-'Working Schedules'!N42 | J10: =-'Working Schedules'!O42
B11: Changes in NWC | C11: =-'Working Capital Schedule'!M21 | D11: =-'Working Capital Schedule'!N21 | E11: =-'Working Capital Schedule'!O21 | F11: =-'Working Capital Schedule'!P21 | G11: =-'Working Capital Schedule'!Q21 | H11: =-'Working Capital Schedule'!R21 | I11: =-'Working Capital Schedule'!S21 | J11: =-'Working Capital Schedule'!T21
B12: Free Cash Flow | C12: =SUM(C8:C11) | D12: =SUM(D8:D11) | E12: =SUM(E8:E11) | F12: =SUM(F8:F11) | G12: =SUM(G8:G11) | H12: =SUM(H8:H11) | I12: =SUM(I8:I11) | J12: =SUM(J8:J11)
B13: Discount Period | C13: 1 | D13: 2 | E13: 3 | F13: 4 | G13: 5 | H13: 6 | I13: 7 | J13: 8
B15: PV of FCF | C15: =C12/(1+$N$9)^C13 | D15: =D12/(1+$N$9)^D13 | E15: =E12/(1+$N$9)^E13 | F15: =F12/(1+$N$9)^F13 | G15: =G12/(1+$N$9)^G13 | H15: =H12/(1+$N$9)^H13 | I15: =I12/(1+$N$9)^I13 | J15: =J12/(1+$N$9)^J13 | K15: Sensitivity Analysis | R15: Horizontal axis | T15: WACC
R16: Vertical axis | T16: Terminal Growth
B18: Terminal Growth Rate (g) | C18: 0.06 | K18: =IF(C28<0,"",C28) | L18: 0.08 | M18: =L18+0.5% | N18: =M18+0.5% | O18: =N18+0.5% | P18: =O18+0.5% | Q18: 0.10692211 | R18: 0.11 | S18: =R18+0.5% | T18: =S18+0.5%
B19: Terminal Year FCF | C19: =J12 | K19: 0.05 | M19: 814.22962 | N19: 715.73371 | O19: 639.14356 | P19: 577.88713 | Q19: 510.86666 | R19: 486.04066 | S19: 450.73224 | T19: 420.47822
B20: Terminal Value | C20: =C19*(1+C18)/(N9-C18) | K20: =K19+0.5% | L20: 1114.6901 | M20: 933.35693 | N20: 803.85529 | O20: 706.74796 | P20: 631.2365 | Q20: 550.72373 | R20: 521.44096 | S20: 480.28518 | T20: 445.47157
B21: PV of Terminal Value | C21: =C20/(1+N9)^J13 | K21: =K20+0.5% | L21: 1368.3481 | M21: 1100.1352 | N21: 921.35074 | O21: 793.66791 | P21: 697.92321 | Q21: 599.0751 | R21: 563.92132 | S21: 515.21138 | T21: 474.63047
B22: Sum of OV of FCF | C22: =SUM(C15:J15) | K22: =K21+0.5% | L22: 1791.1114 | M22: 1350.3025 | N22: 1085.8444 | O22: 909.56117 | P22: 783.66326 | Q22: 658.9601 | R22: 615.84177 | S22: 557.12281 | T22: 509.09099
B23: Enterprise Value | C23: =C21+C22 | K23: =K22+0.5% | L23: 2636.6381 | M23: 1767.2481 | N23: 1332.5848 | O23: 1071.8117 | P23: 897.98333 | Q23: 735.06438 | R23: 680.74232 | S23: 608.3479 | T23: 550.44361
B24: Cash | C24: =BS!L45 | K24: =K23+0.5% | L24: 5173.2181 | M24: 2601.1392 | N24: 1743.8189 | O24: 1315.1876 | P24: 1058.0314 | Q24: 835.00928 | R24: 764.18589 | S24: 672.37926 | T24: 600.98571
B25: Debt | C25: =-BS!L17 | K25: =K24+0.5% | M25: 5102.8127 | N25: 2566.287 | O25: 1720.814 | P25: 1298.1036 | Q25: 972.07791 | R25: 875.44398 | S25: 754.70529 | T25: 664.16333
B26: Equity Value | C26: =SUM(C23:C25) | K26: =K25+0.5% | N26: 5033.6914 | O26: 2532.0668 | P26: 1698.2238 | Q26: 1171.6718 | R26: 1031.2053 | S26: 864.47334 | T26: 745.3917
B27: Shares Outstanding | C27: 72.74 | K27: =K26+0.5% | O27: 4965.8253 | P27: 2498.4643 | Q27: 1489.2144 | R27: 1264.8473 | S27: 1018.1486 | T27: 853.69619
B28: Per Share Value | C28: =C26/C27

Sheet Beta Calculation
B2: Beta Calculation | E2: Beta Calculation Using Weekly Prices of last 5 years | I2: Beta | K2: Beta Calculation Using MOnthly Prices of last 5 years | O2: Beta
I3: =SLOPE(G5:G273,I5:I273) | O3: =SLOPE(M5:M65,O5:O65)
B4: Adjusted Beta | C4: 0.67×Raw Beta+0.33 | E4: Date | F4: Price | G4: % Change | H4: Nifty FMCG | I4: % Change | K4: Date | L4: Price | M4: % Change | N4: Nifty FMCG | O4: % Change
E5: 46173 | F5: 1246.7 | G5: =LN(F5/F6) | H5: 48302.45 | I5: =LN(H5/H6) | K5: 46143 | L5: 1270 | M5: =LN(L5/L6) | N5: 49383.35 | O5: =LN(N5/N6)
B6: Raw Beta | C6: =O3 | E6: 46166 | F6: 1270 | G6: =LN(F6/F7) | H6: 49383.35 | I6: =LN(H6/H7) | K6: 46113 | L6: 1325.6 | M6: =LN(L6/L7) | N6: 51072.1 | O6: =LN(N6/N7)
B7: Adjusted Beta | C7: =0.67*C6+0.33 | E7: 46159 | F7: 1282.1 | G7: =LN(F7/F8) | H7: 50249.8 | I7: =LN(H7/H8) | K7: 46082 | L7: 1218.8 | M7: =LN(L7/L8) | N7: 45538.65 | O7: =LN(N7/N8)
E8: 46152 | F8: 1320.7 | G8: =LN(F8/F9) | H8: 51051.35 | I8: =LN(H8/H9) | K8: 46054 | L8: 1380.8 | M8: =LN(L8/L9) | N8: 51142.2 | O8: =LN(N8/N9)
E9: 46145 | F9: 1280.8 | G9: =LN(F9/F10) | H9: 51165.9 | I9: =LN(H9/H10) | K9: 46023 | L9: 1362.6 | M9: =LN(L9/L10) | N9: 51215.2 | O9: =LN(N9/N10)
E10: 46138 | F10: 1325.6 | G10: =LN(F10/F11) | H10: 51072.1 | I10: =LN(H10/H11) | K10: 45992 | L10: 1443.7 | M10: =LN(L10/L11) | N10: 55475.65 | O10: =LN(N10/N11)
E11: 46131 | F11: 1391.9 | G11: =LN(F11/F12) | H11: 50766.25 | I11: =LN(H11/H12) | K11: 45962 | L11: 1451.6 | M11: =LN(L11/L12) | N11: 55595.8 | O11: =LN(N11/N12)
E12: 46124 | F12: 1302.9 | G12: =LN(F12/F13) | H12: 49657.75 | I12: =LN(H12/H13) | K12: 45931 | L12: 1431.4 | M12: =LN(L12/L13) | N12: 56208.5 | O12: =LN(N12/N13)
E13: 46117 | F13: 1268.2 | G13: =LN(F13/F14) | H13: 48194.05 | I13: =LN(H13/H14) | K13: 45901 | L13: 1324.3 | M13: =LN(L13/L14) | N13: 54710.7 | O13: =LN(N13/N14)
E14: 46110 | F14: 1221.2 | G14: =LN(F14/F15) | H14: 46232.15 | I14: =LN(H14/H15) | K14: 45870 | L14: 1311 | M14: =LN(L14/L15) | N14: 56141.85 | O14: =LN(N14/N15)
E15: 46103 | F15: 1253.8 | G15: =LN(F15/F16) | H15: 46427.2 | I15: =LN(H15/H16) | K15: 45839 | L15: 1340.2 | M15: =LN(L15/L16) | N15: 55812.15 | O15: =LN(N15/N16)
E16: 46096 | F16: 1300.1 | G16: =LN(F16/F17) | H16: 47007.55 | I16: =LN(H16/H17) | K16: 45809 | L16: 1428.1 | M16: =LN(L16/L17) | N16: 54883.9 | O16: =LN(N16/N17)
E17: 46089 | F17: 1314.4 | G17: =LN(F17/F18) | H17: 47924.15 | I17: =LN(H17/H18) | K17: 45778 | L17: 1520.1 | M17: =LN(L17/L18) | N17: 55283 | O17: =LN(N17/N18)
E18: 46082 | F18: 1389.8 | G18: =LN(F18/F19) | H18: 49970.6 | I18: =LN(H18/H19) | K18: 45748 | L18: 1563.9 | M18: =LN(L18/L19) | N18: 56445.35 | O18: =LN(N18/N19)
E19: 46075 | F19: 1380.8 | G19: =LN(F19/F20) | H19: 51142.2 | I19: =LN(H19/H20) | K19: 45717 | L19: 1401.3 | M19: =LN(L19/L20) | N19: 53589.8 | O19: =LN(N19/N20)
... E65: 45753 | F65: 1476.9 | G65: =LN(F65/F66) | H65: 55741.1 | I65: =LN(H65/H66) | K65: 44317 | L65: 612.45 | M65: =LN(L65/L66) | N65: 35243.1 | O65: =LN(N65/N66)
E66: 45746 | F66: 1427.35 | G66: =LN(F66/F67) | H66: 53830.7 | I66: =LN(H66/H67) | K66: 44287 | L66: 519.55 | N66: 33623.45
E67: 45739 | F67: 1401.3 | G67: =LN(F67/F68) | H67: 53589.8 | I67: =LN(H67/H68)
E68: 45732 | F68: 1391.6 | G68: =LN(F68/F69) | H68: 52986.05 | I68: =LN(H68/H69)
E69: 45725 | F69: 1353.7 | G69: =LN(F69/F70) | H69: 51879.25 | I69: =LN(H69/H70)
E70: 45718 | F70: 1327.85 | G70: =LN(F70/F71) | H70: 51891.8 | I70: =LN(H70/H71)
E71: 45711 | F71: 1284.45 | G71: =LN(F71/F72) | H71: 50689 | I71: =LN(H71/H72)
E72: 45704 | F72: 1306.5 | G72: =LN(F72/F73) | H72: 52098.15 | I72: =LN(H72/H73)
E73: 45697 | F73: 1364.4 | G73: =LN(F73/F74) | H73: 53138.55 | I73: =LN(H73/H74)
E74: 45690 | F74: 1427.5 | G74: =LN(F74/F75) | H74: 55113.3 | I74: =LN(H74/H75)
E75: 45683 | F75: 1424 | G75: =LN(F75/F76) | H75: 56691.95 | I75: =LN(H75/H76)
E76: 45676 | F76: 1469.75 | G76: =LN(F76/F77) | H76: 56069.35 | I76: =LN(H76/H77)
E77: 45669 | F77: 1427.55 | G77: =LN(F77/F78) | H77: 55800.85 | I77: =LN(H77/H78)
E78: 45662 | F78: 1539.15 | G78: =LN(F78/F79) | H78: 57117.7 | I78: =LN(H78/H79)
... E273: 44297 | F273: 519.05 | G273: =LN(F273/F274) | H273: 34853.15 | I273: =LN(H273/H274)
E274: 44290 | F274: 537.2 | H274: 35253.1

Sheet Company & Market Insights
B2: United Spirits Company Insights
N3: (in Millions)
B4: Product Segments | C4: 2014 | D4: =C4+1 | E4: =D4+1 | F4: =E4+1 | G4: =F4+1 | H4: =G4+1 | I4: =H4+1 | J4: =I4+1 | K4: =J4+1 | ... N4: =M4+1
B6: Popular Vol | C6: 87.7 | D6: 82.06 | E6: 59 | F6: 53.2 | G6: 41.3 | H6: 40 | I6: 38.85 | J6: 33.5 | K6: 36.41 | L6: 24.65 | M6: 11.1 | N6: 10.88
D7: =LN(D6/C6) | E7: =LN(E6/D6) | F7: =LN(F6/E6) | G7: =LN(G6/F6) | H7: =LN(H6/G6) | I7: =LN(I6/H6) | J7: =LN(J6/I6) | K7: =LN(K6/J6) | ... N7: =LN(N6/M6)
B8: Prestige & Above (P&A) Vol | C8: 33 | D8: 35 | E8: 34 | F8: 36.8 | G8: 37.2 | H8: 41.6 | I8: 40.9 | J8: 37.2 | K8: 42.74 | L8: 47.85 | M8: 50.3 | N8: 53.12
D9: =LN(D8/C8) | E9: =LN(E8/D8) | F9: =LN(F8/E8) | G9: =LN(G8/F8) | H9: =LN(H8/G8) | I9: =LN(I8/H8) | J9: =LN(J8/I8) | K9: =LN(K8/J8) | ... N9: =LN(N8/M8)
B10: Total Sales Volume | C10: =C8+C6 | D10: =D8+D6 | E10: =E8+E6 | F10: =F8+F6 | G10: =G8+G6 | H10: =H8+H6 | I10: =I8+I6 | J10: =J8+J6 | ... N10: =N8+N6
D11: =LN(D10/C10) | E11: =LN(E10/D10) | F11: =LN(F10/E10) | G11: =LN(G10/F10) | H11: =LN(H10/G10) | I11: =LN(I10/H10) | J11: =LN(J10/I10) | K11: =LN(K10/J10) | ... N11: =LN(N10/M10)
B13: CAGR in P&A Segment | C13: =_xlfn.RRI(10,C8,N8)
B15: Segment Tier | C15: Category / Product Name | D15: Brand Positioning & Pricing Sub-Tier | E15: Consolidated Value Matrices & Revenue Benchmarks
B16: Prestige & Above (P&A) | C16: McDowell's No.1 Whisky | D16: Lower Prestige | E16: > ₹1,000 Crore Brand
B17: Prestige & Above (P&A) | C17: Royal Challenge | D17: Mid Prestige | E17: > ₹1,000 Crore Brand
B18: Prestige & Above (P&A) | C18: Johnnie Walker (Blue, Gold, Black, Double Black, Red, Blonde Label) | D18: Luxury & Premium Scotch | E18: > ₹1,000 Crore Brand
B19: Prestige & Above (P&A) | C19: Black & White | D19: Premium Scotch | E19: ₹500 - ₹1,000 Crore Brand
B20: Prestige & Above (P&A) | C20: Black Dog (Triple Gold Reserve, Black Reserve, Millard's Private Reserve) | D20: Premium Scotch | E20: ₹500 - ₹1,000 Crore Brand
B21: Prestige & Above (P&A) | C21: Signature (Premier, Rare) | D21: Upper Prestige | E21: ₹500 - ₹1,000 Crore Brand
B22: Prestige & Above (P&A) | C22: Royal Challenge American Pride | D22: Upper Prestige | E22: Prestige Sub-Tier
B23: Prestige & Above (P&A) | C23: Godawan (01 Rich & Rounded, 02 Fruit & Spice) | D23: Luxury Malts (Artisanal Craft) | E23: High-Growth Luxury Core
B24: Prestige & Above (P&A) | C24: McDowell's & Co Distiller's Batch | D24: Luxury Malts | E24: Premium Innovation Core
B25: Prestige & Above (P&A) | C25: Don Julio Tequila | D25: Premium Luxury Spirits | E25: High-Growth Tequila Tier
B26: Prestige & Above (P&A) | C26: Smirnoff Vodka (Core & Flavors: Mirchi Mango, Minty Jamun, Zesty Lime) | D26: White Spirits / Flavour Range | E26: Premium Spirit Core
... B32: Popular Segment | C32: Mass-Market Brandies / Regional Spirits | D32: Value / Heritage Spirit Lines | E32: Mass Value Contribution

Sheet Cashflow
C2: 2017 | D2: =C2+1 | E2: =D2+1 | F2: =E2+1 | G2: =F2+1 | H2: =G2+1 | I2: =H2+1 | J2: =I2+1 | K2: =J2+1 | L2: =K2+1
A4: x | B4: Cash from Operating Activity - | C4: =C5+C11+C12 | D4: =D5+D11+D12 | E4: =E5+E11+E12 | F4: =F5+F11+F12 | G4: =G5+G11+G12 | H4: =H5+H11+H12 | I4: =I5+I11+I12 | J4: =J5+J11+J12 | ... L4: =L5+L11+L12
B5: Profit from operations | C5: 709 | D5: 1372 | E5: 1569 | F5: 1536 | G5: 1121 | H5: 1640 | I5: 1448 | J5: 2100 | K5: 2319 | L5: 2368
B6: Receivables | C6: -656 | D6: 106 | E6: 84 | F6: 271 | G6: 65 | H6: -205 | I6: -276 | J6: -1045 | K6: -321 | L6: -356
B7: Inventory | C7: 38 | D7: 8 | E7: -15 | F7: 7 | G7: -124 | H7: -105 | I7: -262 | J7: 163 | K7: -242 | L7: -359
B8: Payables | C8: 217 | D8: 251 | E8: -60 | F8: -201 | G8: 209 | H8: 123 | I8: 203 | J8: 132 | K8: 250 | L8: 223
B9: Loans Advances | C9: 0 | D9: 0 | E9: 0 | F9: 0 | G9: 0 | H9: 0 | I9: -96 | J9: 154 | K9: -42 | L9: 0
B10: Other WC items | C10: 539 | D10: -399 | E10: 208 | F10: -247 | G10: 654 | H10: -18 | I10: -134 | J10: -49 | K10: 146 | L10: -87
B11: Working capital changes | C11: =SUM(C6:C10) | D11: =SUM(D6:D10) | E11: =SUM(E6:E10) | F11: =SUM(F6:F10) | G11: =SUM(G6:G10) | H11: =SUM(H6:H10) | I11: =SUM(I6:I10) | J11: =SUM(J6:J10) | ... L11: =SUM(L6:L10)
B12: Direct taxes | C12: -200 | D12: -413 | E12: -837 | F12: -583 | G12: -107 | H12: -457 | I12: -268 | J12: -337 | K12: -163 | L12: -334
B13: Other operating items | C13: 0 | D13: 0 | E13: 0 | F13: 0 | G13: 0 | H13: 0 | I13: 0 | J13: 0 | K13: 0 | L13: 4
A15: x | B15: Cash from Investing Activity - | C15: =SUM(C16:C26) | D15: =SUM(D16:D26) | E15: =SUM(E16:E26) | F15: =SUM(F16:F26) | G15: =SUM(G16:G26) | H15: =SUM(H16:H26) | I15: =SUM(I16:I26) | J15: =SUM(J16:J26) | ... L15: =SUM(L16:L26)
B16: Fixed assets purchased | C16: -311 | D16: -184 | E16: -173 | F16: -212 | G16: -174 | H16: -134 | I16: -137 | J16: -98 | K16: -162 | L16: -181 | V16: Net Change in Cash=CFO+CFI+CFF
B17: Fixed assets sold | C17: 53 | D17: 154 | E17: 96 | F17: 12 | G17: 35 | H17: 38 | I17: 27 | J17: 19 | K17: 1 | L17: 253 | Q17: 2027 | R17: =Q17+1 | S17: =R17+1 | T17: =S17+1 | W17: CFO=PAT+Depreciation−ΔWC
B18: Investments purchased | C18: 0 | D18: 0 | E18: 0 | F18: 0 | G18: 0 | H18: -1436 | I18: -8517 | J18: -1032 | K18: -1391 | L18: -1879 | P18: PAT | Q18: =PL!M23 | R18: =PL!N23 | S18: =PL!O23 | T18: =PL!P23
B19: Investments sold | C19: 11 | D19: 130 | E19: 32 | F19: 0 | G19: 0 | H19: 1222 | I19: 8502 | J19: 751 | K19: 1163 | L19: 1701 | P19: DEP | Q19: =-PL!M14 | R19: =-PL!N14 | S19: =-PL!O14 | T19: =-PL!P14
B20: Interest received | C20: 20 | D20: 4 | E20: 6 | F20: 6 | G20: 11 | H20: 6 | I20: 20 | J20: 42 | K20: 36 | L20: 67 | P20: change in wc | Q20: =-'Working Capital Schedule'!M24 | R20: =-'Working Capital Schedule'!N24 | S20: =-'Working Capital Schedule'!O24 | T20: =-'Working Capital Schedule'!P24
B21: Dividends received | C21: 0 | D21: 0 | E21: 0 | F21: 0 | G21: 0 | H21: 0 | I21: 0 | J21: 0 | K21: 0 | L21: 0 | P21: CFO | Q21: =SUM(Q18:Q20) | R21: =SUM(R18:R20) | S21: =SUM(S18:S20) | T21: =SUM(T18:T20)
B22: Invest in subsidiaries | C22: 0 | D22: 0 | E22: 0 | F22: 0 | G22: 0 | H22: 0 | I22: 0 | J22: 0 | K22: 0 | L22: -40 | P22: CFI | Q22: =-'Working Schedules'!H42 | R22: =-'Working Schedules'!I42 | S22: =-'Working Schedules'!J42 | T22: =-'Working Schedules'!K42
B23: Investment in group cos | C23: 0 | D23: 0 | E23: 0 | F23: 0 | G23: -2 | H23: 0 | I23: -32 | J23: -15 | K23: -13 | L23: 0 | P23: CFF
B24: Redemp n Canc of Shares | C24: 0 | D24: 0 | E24: 0 | F24: 0 | G24: 30 | H24: 0 | I24: 32 | J24: 0 | K24: 0 | L24: 0 | P24: dividend pay | Q24: =BS!M11 | R24: =BS!N11 | S24: =BS!O11 | T24: =BS!P11
B25: Acquisition of companies | C25: 0 | D25: 0 | E25: -27 | F25: 0 | G25: 0 | H25: 0 | I25: 0 | J25: 0 | K25: 0 | L25: 0 | P25: intererst paid | Q25: =PL!M18 | R25: =PL!N18 | S25: =PL!O18 | T25: =PL!P18
