Workbook

Sheet Scenarios
C2: United Spirits Economic Scenarios
C4: Scenario Switch | D4: 1
C8: Sales Growth % Scenarios | H8: 2027 | I8: =H8+1 -> 2028 | J8: =I8+1 -> 2029 | K8: =J8+1 -> 2030 | L8: =K8+1 -> 2031 | M8: =L8+1 -> 2032 | N8: =M8+1 -> 2033 | O8: =N8+1 -> 2034
C10: Sales Growth % | H10: =CHOOSE($D$4,H12,H13,H14) -> 0.09 | I10: =CHOOSE($D$4,I12,I13,I14) -> 0.09 | J10: =CHOOSE($D$4,J12,J13,J14) -> 0.08 | K10: =CHOOSE($D$4,K12,K13,K14) -> 0.07 | L10: =CHOOSE($D$4,L12,L13,L14) -> 0.065 | M10: =CHOOSE($D$4,M12,M13,M14) -> 0.065 | N10: =CHOOSE($D$4,N12,N13,N14) -> 0.065 | O10: =CHOOSE($D$4,O12,O13,O14) -> 0.065
C12: Base | H12: 0.09 | I12: 0.09 | J12: 0.08 | K12: 0.07 | L12: 0.065 | M12: 0.065 | N12: 0.065 | O12: 0.065
C13: Best | H13: 0.11 | I13: 0.11 | J13: 0.1 | K13: 0.09 | L13: 0.08 | M13: 0.07 | N13: 0.07 | O13: 0.07
C14: Bear | H14: 0.06 | I14: 0.06 | J14: 0.05 | K14: 0.05 | L14: 0.05 | M14: 0.05 | N14: 0.05 | O14: 0.05
C17: Gross Profit Margin % Scenarios | H17: 2027 | I17: =H17+1 -> 2028 | J17: =I17+1 -> 2029 | K17: =J17+1 -> 2030 | L17: =K17+1 -> 2031 | M17: =L17+1 -> 2032 | N17: =M17+1 -> 2033 | O17: =N17+1 -> 2034
C19: Gross Profi Margin % | H19: =CHOOSE($D$4,H21,H22,H23) -> 0.455 | I19: =CHOOSE($D$4,I21,I22,I23) -> 0.46 | J19: =CHOOSE($D$4,J21,J22,J23) -> 0.465 | K19: =CHOOSE($D$4,K21,K22,K23) -> 0.47 | L19: =CHOOSE($D$4,L21,L22,L23) -> 0.47 | M19: =CHOOSE($D$4,M21,M22,M23) -> 0.47 | N19: =CHOOSE($D$4,N21,N22,N23) -> 0.47 | O19: =CHOOSE($D$4,O21,O22,O23) -> 0.47
C21: Base | H21: 0.455 | I21: 0.46 | J21: 0.465 | K21: 0.47 | L21: 0.47 | M21: 0.47 | N21: 0.47 | O21: 0.47
C22: Best | H22: 0.46720587 | I22: 0.48156147 | J22: 0.49591708 | K22: 0.51027268 | L22: 0.51027268 | M22: 0.51027268 | N22: 0.51027268 | O22: 0.51027268
C23: Bear | H23: 0.435 | I23: 0.435 | J23: 0.44 | K23: 0.44 | L23: 0.44 | M23: 0.44 | N23: 0.44 | O23: 0.44

Sheet PPT Sheet
B2: NSE CODE | C2: UNITDSPR
B3: BSE CODE | C3: 532432 | H3: Particulars | I3: Value
B4: CMP | C4: 1345
B5: Share Capital (Rs in Cr.) | C5: 145
B6: Shares Outstanding (Cr.) | C6: 72.74
B7: Face Value | C7: 2
B8: Market Cap (Rs in Cr.) | C8: 96453.24
B9: Enterprice Value (Rs in Cr.) | C9: 93726.24
B10: 52 Week High | C10: 1489
B11: 52 Week Low | C11: 1210

Sheet Valuation Summary
B2: Peer Comparison | M2: =PL!T2 -> CURRENTLY RUNNING: BASE SCENARIO | Q2: Valuation Summary
A3: x | C3: Assumptions
C4: Revenue | D4: EBITDA | E4: EBIT | F4: PAT | Q4: Method | S4: Implied | T4: Weight | U4: Contribution
B5: United Breweries | C5: 0.08 | D5: 0.089177489 | E5: 0.062662338 | F5: 0.04469697
B6: Radico Khaitan Ltd | C6: 0.25 | D6: 0.17157025 | E6: 0.14644628 | F6: 0.10198347 | Q6: EV/EBITDA | S6: =(K29*K13+S14-S13)/S15 -> 1410.824 | T6: 0.6 | U6: =T6*S6 -> 846.49438
B7: Allied Blenders | C7: 0.08 | D7: 0.13815957 | E7: 0.12413969 | F7: 0.058373694 | Q7: P/E | S7: =M29*M13/S15 -> 1675.3907 | T7: 0.2 | U7: =T7*S7 -> 335.07813
Q8: EV/EBIT | S8: =(L29*L13+S14-S13)/S15 -> 1408.3011 | T8: 0.05 | U8: =T8*S8 -> 70.415053
Q9: DCF | S9: =DCF!C28 -> 642.24 | T9: 0.15 | U9: =T9*S9 -> 96.336
C10: 2026 | J10: =C10+1 -> 2027 | Q10: Per Share Value | U10: =SUM(U6:U9) -> 1348.3236
A12: x | B12: Particulars | C12: Mkt Cap | D12: EV | E12: Revenue | F12: EBITDA | G12: EBIT | H12: PAT | J12: Revenue | K12: EBITDA | L12: EBIT | M12: PAT
B13: United Spirits | C13: ='Ratio Analysis'!L34 -> 96453.24 | D13: ='Ratio Analysis'!L37 -> 93726.24 | E13: =PL!L5 -> 12467 | F13: =PL!L12 -> 2279 | G13: =PL!L14 -> 1990 | H13: =PL!L22 -> 1838 | J13: =PL!M5 -> 13589.03 | K13: =PL!M12 -> 2547.3242 | L13: =PL!M14 -> 2170.3113 | M13: =PL!M22 -> 1708.6379 | Q13: Debt | S13: 407
B14: United Breweries | C14: 35605 | D14: 36350 | E14: 9240 | F14: 824 | G14: 579 | H14: 413 | J14: =E14*(1+C5) -> 9979.2 | K14: =J14*D5 -> 889.92 | L14: =J14*E5 -> 625.32 | M14: =J14*F5 -> 446.04 | Q14: Cash | S14: 3134
B15: Radico Khaitan Ltd | C15: 50274 | D15: 50883 | E15: 6050 | F15: 1038 | G15: 886 | H15: 617 | J15: =E15*(1+C6) -> 7562.5 | K15: =J15*D6 -> 1297.5 | L15: =J15*E6 -> 1107.5 | M15: =J15*F6 -> 771.25 | Q15: Shares O/S | S15: 72.74
B16: Allied Blenders | C16: 17640 | D16: 18635 | E16: 3923 | F16: 542 | G16: 487 | H16: 229 | J16: =E16*(1+C7) -> 4236.84 | K16: =J16*D7 -> 585.36 | L16: =J16*E7 -> 525.96 | M16: =J16*F7 -> 247.32
A19: x | B19: Multiples
E20: 2026 | J20: =1+E20 -> 2027
B22: Particulars | E22: EV/Revenue | F22: EV/EBITDA | G22: EV/EBIT | H22: P/E | J22: EV/Revenue | K22: EV/EBITDA | L22: EV/EBIT | M22: P/E
A23: x | B23: United Spirits | E23: =$D$13/E13 -> 7.5179466 | F23: =$D$13/F13 -> 41.126038 | G23: =$D$13/G13 -> 47.098613 | H23: =$C$13/H13 -> 52.47728 | J23: =$D$13/J13 -> 6.8971987 | K23: =$D$13/K13 -> 36.793998 | L23: =$D$13/L13 -> 43.185621 | M23: =$C$13/M13 -> 56.450368
B24: United Breweries | E24: =$D$14/E14 -> 3.9339827 | F24: =$D$14/F14 -> 44.114078 | G24: =$D$14/G14 -> 62.780656 | H24: =$C$14/H14 -> 86.210654 | J24: =$D$14/J14 -> 3.6425766 | K24: =$D$14/K14 -> 40.846368 | L24: =$D$14/L14 -> 58.130237 | M24: =$C$14/M14 -> 79.824679
B25: Radico Khaitan Ltd | E25: =$D$15/E15 -> 8.4104132 | F25: =$D$15/F15 -> 49.020231 | G25: =$D$15/G15 -> 57.430023 | H25: =$C$15/H15 -> 81.481361 | J25: =$D$15/J15 -> 6.7283306 | K25: =$D$15/K15 -> 39.216185 | L25: =$D$15/L15 -> 45.944018 | M25: =$C$15/M15 -> 65.185089
B26: Allied Blenders | E26: =$D$16/E16 -> 4.7501912 | F26: =$D$16/F16 -> 34.381919 | G26: =$D$16/G16 -> 38.264887 | H26: =$C$16/H16 -> 77.030568 | J26: =$D$16/J16 -> 4.3983252 | K26: =$D$16/K16 -> 31.83511 | L26: =$D$16/L16 -> 35.430451 | M26: =$C$16/M16 -> 71.3246
B28: Mean | E28: =AVERAGE(E24:E26) -> 5.6981957 | F28: =AVERAGE(F24:F26) -> 42.505409 | G28: =AVERAGE(G24:G26) -> 52.825189 | H28: =AVERAGE(H24:H26) -> 81.574194 | J28: =AVERAGE(J24:J26) -> 4.9230774 | K28: =AVERAGE(K24:K26) -> 37.299221 | L28: =AVERAGE(L24:L26) -> 46.501569 | M28: =AVERAGE(M24:M26) -> 72.111456
B29: Median | E29: =MEDIAN(E24:E26) -> 4.7501912 | F29: =MEDIAN(F24:F26) -> 44.114078 | G29: =MEDIAN(G24:G26) -> 57.430023 | H29: =MEDIAN(H24:H26) -> 81.481361 | J29: =MEDIAN(J24:J26) -> 4.3983252 | K29: =MEDIAN(K24:K26) -> 39.216185 | L29: =MEDIAN(L24:L26) -> 45.944018 | M29: =MEDIAN(M24:M26) -> 71.3246
A32: x | B32: Valuation using Mean Multiples
E33: 2026 | J33: =1+E33 -> 2027
E35: EV/Revenue | F35: EV/EBITDA | G35: EV/EBIT | H35: P/E | J35: EV/Revenue | K35: EV/EBITDA | L35: EV/EBIT | M35: P/E
B36: Enterprise Value & Market Cap(P/E) | E36: =E28*E13 -> 71039.406 | F36: =F28*F13 -> 96869.828 | G36: =G28*G13 -> 105122.13 | H36: =H28*H13 -> 149933.37 | J36: =J28*J13 -> 66899.847 | K36: =K28*K13 -> 95013.207 | L36: =L28*L13 -> 100922.88 | M36: =M28*M13 -> 123212.37
B37: Debt | E37: 407 | F37: 407 | G37: 407 | J37: 407 | K37: 407 | L37: 407
B38: Cash | E38: 3134 | F38: 3134 | G38: 3134 | J38: 3134 | K38: 3134 | L38: 3134
B39: Equity Value | E39: =E36-E37+E38 -> 73766.406 | F39: =F36-F37+F38 -> 99596.828 | G39: =G36-G37+G38 -> 107849.13 | J39: =J36-J37+J38 -> 69626.847 | K39: =K36-K37+K38 -> 97740.207 | L39: =L36-L37+L38 -> 103649.88
B40: Shares O/S | E40: 72.74 | F40: 72.74 | G40: 72.74 | H40: 72.74 | J40: 72.74 | K40: 72.74 | L40: 72.74 | M40: 72.74
A41: x | B41: Per Share Value | E41: =E39/E40 -> 1014.1106 | F41: =F39/F40 -> 1369.2168 | G41: =G39/G40 -> 1482.666 | H41: =H36/H40 -> 2061.2231 | J41: =J39/J40 -> 957.20164 | K41: =K39/K40 -> 1343.6927 | L41: =L39/L40 -> 1424.9365 | M41: =M36/M40 -> 1693.8736
B44: Valuation using Median Multiples
E45: 2026 | J45: =1+E45 -> 2027
E47: EV/Revenue | F47: EV/EBITDA | G47: EV/EBIT | H47: P/E | J47: EV/Revenue | K47: EV/EBITDA | L47: EV/EBIT | M47: P/E
B48: Enterprise Value & Market Cap(P/E) | E48: =E29*E13 -> 59220.633 | F48: =F29*F13 -> 100535.98 | G48: =G29*G13 -> 114285.74 | H48: =H29*H13 -> 149762.74 | J48: =J29*J13 -> 59768.973 | K48: =K29*K13 -> 99896.335 | L48: =L29*L13 -> 99712.819 | M48: =M29*M13 -> 121867.92
B49: Debt | E49: 407 | F49: 407 | G49: 407 | J49: 407 | K49: 407 | L49: 407
B50: Cash | E50: 3134 | F50: 3134 | G50: 3134 | J50: 3134 | K50: 3134 | L50: 3134
B51: Equity Value | E51: =E48-E49+E50 -> 61947.633 | F51: =F48-F49+F50 -> 103262.98 | G51: =G48-G49+G50 -> 117012.74 | J51: =J48-J49+J50 -> 62495.973 | K51: =K48-K49+K50 -> 102623.34 | L51: =L48-L49+L50 -> 102439.82
B52: Shares O/S | E52: 72.74 | F52: 72.74 | G52: 72.74 | H52: 72.74 | J52: 72.74 | K52: 72.74 | L52: 72.74 | M52: 72.74
...

Sheet Summary
B1: United Spirits Ltd
B2: Summary Outputs Base Case
B4: Particulars | D4: 2017 | E4: 2018 | F4: 2019 | G4: 2020 | H4: 2021 | I4: 2022 | J4: 2023 | K4: 2024 | L4: 2025 | M4: 2026 | N4: 2027 | O4: 2028 | P4: 2029 | Q4: 2030 | R4: 2031 | S4: 2032 | T4: 2033 | U4: 2034
B6: Net Revenue | D6: 8817.5 | E6: 8590.6 | F6: 9340.8 | G6: 9325.4 | H6: 8131.3 | I6: 9712.4 | J6: 10612 | K6: 11321 | L6: 12069 | M6: 12467 | N6: 13589.03 | O6: 14812.043 | P6: 15997.006 | Q6: 17116.797 | R6: 18229.388 | S6: 19414.299 | T6: 20676.228 | U6: 22020.183
B7: Growth | E7: -0.025732917 | F7: 0.08732801 | G7: -0.0016486811 | H7: -0.12804813 | I7: 0.19444615 | J7: 0.092623862 | K7: 0.066811157 | L7: 0.066071902 | M7: 0.032977049 | N7: 0.09 | O7: 0.09 | P7: 0.08 | Q7: 0.07 | R7: 0.065 | S7: 0.065 | T7: 0.065 | U7: 0.065
B10: COGS | D10: 5151.3 | E10: 4557.3 | F10: 4966.4 | G10: 5370 | H10: 4807.5 | I10: 5680.9 | J10: 6503 | K10: 6542 | L10: 6860 | M10: 6674 | N10: 7406.0213 | O10: 7998.5031 | P10: 8558.3983 | Q10: 9071.9022 | R10: 9661.5758 | S10: 10289.578 | T10: 10958.401 | U10: 11670.697
B11: Growth | E11: -0.1153107 | F11: 0.089768064 | G11: 0.081266108 | H11: -0.1047486 | I11: 0.18167447 | J11: 0.14471299 | K11: 0.005997232 | L11: 0.048608988 | M11: -0.027113703 | N11: 0.10968255 | O11: 0.08 | P11: 0.07 | Q11: 0.06 | R11: 0.065 | S11: 0.065 | T11: 0.065 | U11: 0.065
B14: Gross Profit | D14: 3666.2 | E14: 4033.3 | F14: 4374.4 | G14: 3955.4 | H14: 3323.8 | I14: 4031.5 | J14: 4109 | K14: 4779 | L14: 5209 | M14: 5793 | N14: 6183.0087 | O14: 6813.5396 | P14: 7438.6078 | Q14: 8044.8944 | R14: 8567.8125 | S14: 9124.7203 | T14: 9717.8271 | U14: 10349.486
B15: Gross Profit Margin | D15: 0.41578679 | E15: 0.46950155 | F15: 0.46831107 | G15: 0.42415339 | H15: 0.40876613 | I15: 0.41508793 | J15: 0.38720317 | K15: 0.42213585 | L15: 0.43160162 | M15: 0.46466672 | N15: 0.455 | O15: 0.46 | P15: 0.465 | Q15: 0.47 | R15: 0.47 | S15: 0.47 | T15: 0.47 | U15: 0.47
B16: Growth | E16: 0.10013093 | F16: 0.084570947 | G16: -0.095784565 | H16: -0.15968044 | I16: 0.21291895 | J16: 0.019223614 | K16: 0.1630567 | L16: 0.089976983 | M16: 0.11211365 | N16: 0.067324124 | O16: 0.10197802 | P16: 0.09173913 | Q16: 0.081505376 | R16: 0.065 | S16: 0.065 | T16: 0.065 | U16: 0.065
B19: EBIDTA | D19: 991.4 | E19: 1209.2 | F19: 1393.8 | G19: 1571 | H19: 1051.4 | I19: 1595.2 | J19: 1417 | K19: 2000 | L19: 2236 | M19: 2279 | N19: 2547.3242 | O19: 2850.6435 | P19: 3158.6801 | Q19: 3465.3716 | R19: 3690.6208 | S19: 3930.5111 | T19: 4185.9944 | U19: 4458.084
B20: EBIDTA Margin | D20: 0.1124355 | E20: 0.1407585 | F20: 0.14921634 | G20: 0.16846462 | H20: 0.12930282 | I20: 0.16424365 | J20: 0.13352808 | K20: 0.17666284 | L20: 0.18526804 | M20: 0.1828026 | N20: 0.18745445 | O20: 0.19245445 | P20: 0.19745445 | Q20: 0.20245445 | R20: 0.20245445 | S20: 0.20245445 | T20: 0.20245445 | U20: 0.20245445
B21: Growth | E21: 0.21968933 | F21: 0.15266292 | G21: 0.12713445 | H21: -0.33074475 | I21: 0.51721514 | J21: -0.11171013 | K21: 0.4114326 | L21: 0.118 | M21: 0.019230769 | N21: 0.11773767 | O21: 0.11907373 | P21: 0.10805859 | Q21: 0.097094856 | R21: 0.065 | S21: 0.065 | T21: 0.065 | U21: 0.065
B24: EBIT | D24: 802.8 | E24: 1016.9 | F24: 1179.1 | G24: 1285.7 | H24: 752.3 | I24: 1291.4 | J24: 1134 | K24: 1725 | L24: 1953 | M24: 1990 | N24: 2170.3113 | O24: 2433.4848 | P24: 2700.3359 | Q24: 2965.1879 | R24: 3148.079 | S24: 3344.665 | T24: 3555.2941 | U24: 3780.4994
B25: EBIT Margin | D25: 0.091046215 | E25: 0.11837357 | F25: 0.12623116 | G25: 0.13787076 | H25: 0.092519031 | I25: 0.13296405 | J25: 0.10686016 | K25: 0.1523717 | L25: 0.16181954 | M25: 0.1596214 | N25: 0.15971053 | O25: 0.16429097 | P25: 0.16880258 | Q25: 0.17323264 | R25: 0.17269252 | S25: 0.17227844 | T25: 0.17195081 | U25: 0.17168338
B26: Growth | E26: 0.26669158 | F26: 0.15950438 | G26: 0.090407938 | H26: -0.41487128 | I26: 0.71660242 | J26: -0.12188323 | K26: 0.52116402 | L26: 0.13217391 | M26: 0.018945212 | N26: 0.090608669 | O26: 0.12126074 | P26: 0.10965801 | Q26: 0.09808111 | R26: 0.061679435 | S26: 0.062446352 | T26: 0.062974633 | U26: 0.06334367
B29: Profit After Tax | D29: 93 | E29: 651.9 | F29: 683.6 | G29: 620.6 | H29: 362.1 | I29: 810.6 | J29: 1125.8 | K29: 1408 | L29: 1582 | M29: 1838 | N29: 1708.6379 | O29: 1891.2508 | P29: 2118.6321 | Q29: 2317.6542 | R29: 2489.1953 | S29: 2641.163 | T29: 2836.3987 | U29: 3013.605
B30: PAT Margin | D30: 0.010547207 | E30: 0.07588527 | F30: 0.07318431 | G30: 0.066549424 | H30: 0.044531625 | I30: 0.083460319 | J30: 0.10608745 | K30: 0.12437064 | L30: 0.13107963 | M30: 0.14742921 | N30: 0.12573656 | O30: 0.12768332 | P30: 0.13243929 | Q30: 0.13540233 | R30: 0.13654848 | S30: 0.13604215 | T30: 0.13718163 | U30: 0.1368565
B31: Growth | E31: 6.0096774 | F31: 0.04862709 | G31: -0.092159157 | H31: -0.41653239 | I31: 1.2386081 | J31: 0.38884777 | K31: 0.25066619 | L31: 0.12357955 | M31: 0.16182048 | N31: -0.070381975 | O31: 0.10687629 | P31: 0.12022798 | Q31: 0.093938966 | R31: 0.074014973 | S31: 0.061050923 | T31: 0.073920376 | U31: 0.06247582
B33: Summary Outputs Best Case
B35: Particulars | D35: 2017 | E35: 2018 | F35: 2019 | G35: 2020 | H35: 2021 | I35: 2022 | J35: 2023 | K35: 2024 | L35: 2025 | M35: 2026 | N35: 2027 | O35: 2028 | P35: 2029 | Q35: 2030 | R35: 2031 | S35: 2032 | T35: 2033 | U35: 2034
B37: Net Revenue | D37: 8817.5 | E37: 8590.6 | F37: 9340.8 | G37: 9325.4 | H37: 8131.3 | I37: 9712.4 | J37: 10612 | K37: 11321 | L37: 12069 | M37: 12467 | N37: 13838.37 | O37: 15360.591 | P37: 16896.65 | Q37: 18417.348 | R37: 19890.736 | S37: 21283.088 | T37: 22772.904 | U37: 24367.007
B38: Growth | E38: -0.025732917 | F38: 0.08732801 | G38: -0.0016486811 | H38: -0.12804813 | I38: 0.19444615 | J38: 0.092623862 | K38: 0.066811157 | L38: 0.066071902 | M38: 0.032977049 | N38: 0.11 | O38: 0.11 | P38: 0.1 | Q38: 0.09 | R38: 0.08 | S38: 0.07 | T38: 0.07 | U38: 0.07
B41: COGS | D41: 5151.3 | E41: 4557.3 | F41: 4966.4 | G41: 5370 | H41: 4807.5 | I41: 5680.9 | J41: 6503 | K41: 6542 | L41: 6860 | M41: 6674 | N41: 7373.0023 | O41: 7963.522 | P41: 8517.3126 | Q41: 9019.4785 | R41: 9741.0368 | S41: 10422.909 | T41: 11152.513 | U41: 11933.189
B42: Growth | E42: -0.1153107 | F42: 0.089768064 | G42: 0.081266108 | H42: -0.1047486 | I42: 0.18167447 | J42: 0.14471299 | K42: 0.005997232 | L42: 0.048608988 | M42: -0.027113703 | N42: 0.10473514 | O42: 0.080092162 | P42: 0.069540912 | Q42: 0.058958265 | R42: 0.08 | S42: 0.07 | T42: 0.07 | U42: 0.07
B45: Gross Profit | D45: 3666.2 | E45: 4033.3 | F45: 4374.4 | G45: 3955.4 | H45: 3323.8 | I45: 4031.5 | J45: 4109 | K45: 4779 | L45: 5209 | M45: 5793 | N45: 6465.3677 | O45: 7397.0687 | P45: 8379.3372 | Q45: 9397.8697 | R45: 10149.699 | S45: 10860.178 | T45: 11620.391 | U45: 12433.818
B46: Gross Profit Margin | D46: 0.41578679 | E46: 0.46950155 | F46: 0.46831107 | G46: 0.42415339 | H46: 0.40876613 | I46: 0.41508793 | J46: 0.38720317 | K46: 0.42213585 | L46: 0.43160162 | M46: 0.46466672 | N46: 0.46720587 | O46: 0.48156147 | P46: 0.49591708 | Q46: 0.51027268 | R46: 0.51027268 | S46: 0.51027268 | T46: 0.51027268 | U46: 0.51027268
B47: Growth | E47: 0.10013093 | F47: 0.084570947 | G47: -0.095784565 | H47: -0.15968044 | I47: 0.21291895 | J47: 0.019223614 | K47: 0.1630567 | L47: 0.089976983 | M47: 0.11211365 | N47: 0.11606555 | O47: 0.14410642 | P47: 0.13279159 | Q47: 0.12155287 | R47: 0.08 | S47: 0.07 | T47: 0.07 | U47: 0.07
B50: EBIDTA | D50: 991.4 | E50: 1209.2 | F50: 1393.8 | G50: 1571 | H50: 1051.4 | I50: 1595.2 | J50: 1417 | K50: 2000 | L50: 2236 | M50: 2279 | N50: 2762.9734 | O50: 3287.411 | P50: 3858.7137 | Q50: 4470.3901 | R50: 4828.0214 | S50: 5165.9828 | T50: 5527.6016 | U50: 5914.5338
B51: EBIDTA Margin | D51: 0.1124355 | E51: 0.1407585 | F51: 0.14921634 | G51: 0.16846462 | H51: 0.12930282 | I51: 0.16424365 | J51: 0.13352808 | K51: 0.17666284 | L51: 0.18526804 | M51: 0.1828026 | N51: 0.19966032 | O51: 0.21401593 | P51: 0.22837153 | Q51: 0.24272713 | R51: 0.24272713 | S51: 0.24272713 | T51: 0.24272713 | U51: 0.24272713
B52: Growth | E52: 0.21968933 | F52: 0.15266292 | G52: 0.12713445 | H52: -0.33074475 | I52: 0.51721514 | J52: -0.11171013 | K52: 0.4114326 | L52: 0.118 | M52: 0.019230769 | N52: 0.21236218 | O52: 0.18980915 | P52: 0.173785 | Q52: 0.15851821 | R52: 0.08 | S52: 0.07 | T52: 0.07 | U52: 0.07
B55: EBIT | D55: 802.8 | E55: 1016.9 | F55: 1179.1 | G55: 1285.7 | H55: 752.3 | I55: 1291.4 | J55: 1134 | K55: 1725 | L55: 1953 | M55: 1990 | N55: 2384.9195 | O55: 2866.3352 | P55: 3391.827 | Q55: 3955.3368 | R55: 4262.9835 | S55: 4549.7793 | T55: 4858.8862 | U55: 5191.1953
B56: EBIT Margin | D56: 0.091046215 | E56: 0.11837357 | F56: 0.12623116 | G56: 0.13787076 | H56: 0.092519031 | I56: 0.13296405 | J56: 0.10686016 | K56: 0.1523717 | L56: 0.16181954 | M56: 0.1596214 | N56: 0.17234107 | O56: 0.18660319 | P56: 0.20073962 | Q56: 0.21476147 | R56: 0.21432005 | S56: 0.2137744 | T56: 0.21336261 | U56: 0.21304198
B57: Growth | E57: 0.26669158 | F57: 0.15950438 | G57: 0.090407938 | H57: -0.41487128 | I57: 0.71660242 | J57: -0.12188323 | K57: 0.52116402 | L57: 0.13217391 | M57: 0.018945212 | N57: 0.19845201 | O57: 0.20185824 | P57: 0.18333231 | Q57: 0.16613752 | R57: 0.077780157 | S57: 0.06727585 | T57: 0.067938878 | U57: 0.068392039
B60: Profit After Tax | D60: 93 | E60: 651.9 | F60: 683.6 | G60: 620.6 | H60: 362.1 | I60: 810.6 | J60: 1125.8 | K60: 1408 | L60: 1582 | M60: 1838 | N60: 1869.4193 | O60: 2213.9017 | P60: 2640.6547 | Q60: 3066.2782 | R60: 3342.3167 | S60: 3569.0167 | T60: 3854.2562 | U60: 4119.4045
B61: PAT Margin | D61: 0.010547207 | E61: 0.07588527 | F61: 0.07318431 | G61: 0.066549424 | H61: 0.044531625 | I61: 0.083460319 | J61: 0.10608745 | K61: 0.12437064 | L61: 0.13107963 | M61: 0.14742921 | N61: 0.13508956 | O61: 0.14412868 | P61: 0.15628274 | Q61: 0.16648858 | R61: 0.16803384 | S61: 0.16769262 | T61: 0.16924747 | U61: 0.16905665
B62: Growth | E62: 6.0096774 | F62: 0.04862709 | G62: -0.092159157 | H62: -0.41653239 | I62: 1.2386081 | J62: 0.38884777 | K62: 0.25066619 | L62: 0.12357955 | M62: 0.16182048 | N62: 0.017094271 | O62: 0.18427241 | P62: 0.19276063 | Q62: 0.16118104 | R62: 0.09002396 | S62: 0.067827206 | T62: 0.079921039 | U62: 0.068793634
B64: Summary Outputs Bear Case
B66: Particulars | D66: 2017 | E66: 2018 | F66: 2019 | G66: 2020 | H66: 2021 | I66: 2022 | J66: 2023 | K66: 2024 | L66: 2025 | M66: 2026 | N66: 2027 | O66: 2028 | P66: 2029 | Q66: 2030 | R66: 2031 | S66: 2032 | T66: 2033 | U66: 2034
B68: Net Revenue | D68: 8817.5 | E68: 8590.6 | F68: 9340.8 | G68: 9325.4 | H68: 8131.3 | I68: 9712.4 | J68: 10612 | K68: 11321 | L68: 12069 | M68: 12467 | N68: 13215.02 | O68: 14007.921 | P68: 14708.317 | Q68: 15443.733 | R68: 16215.92 | S68: 17026.716 | T68: 17878.052 | U68: 18771.954
...

Sheet DCF
B2: DCF Valuation | J2: =PL!T2 -> CURRENTLY RUNNING: BASE SCENARIO | N2: WACC Calculation
B4: Particulars | C4: 2027 | D4: =C4+1 -> 2028 | E4: =D4+1 -> 2029 | F4: =E4+1 -> 2030 | G4: =F4+1 -> 2031 | H4: =G4+1 -> 2032 | I4: =H4+1 -> 2033 | J4: =I4+1 -> 2034 | N4: Risk Free Rate | Q4: 0.07 | R4: (10-yr G-Sec)
N5: Rm | Q5: 0.11 | R5: Nifty50 5 Year Monthly Return
B6: EBIT | C6: =PL!M14 -> 2170.3113 | D6: =PL!N14 -> 2433.4848 | E6: =PL!O14 -> 2700.3359 | F6: =PL!P14 -> 2965.1879 | G6: =PL!Q14 -> 3148.079 | H6: =PL!R14 -> 3344.665 | I6: =PL!S14 -> 3555.2941 | J6: =PL!T14 -> 3780.4994 | N6: Market Risk Premium | Q6: =Q5-Q4 -> 0.04 | R6: Rm-Rf
B7: Tax | C7: =Assumptions!E10 -> 0.25 | D7: =Assumptions!F10 -> 0.25 | E7: =Assumptions!G10 -> 0.25 | F7: =Assumptions!H10 -> 0.25 | G7: =Assumptions!I10 -> 0.25 | H7: =Assumptions!J10 -> 0.25 | I7: =Assumptions!K10 -> 0.25 | J7: =Assumptions!L10 -> 0.25 | N7: Beta | Q7: 0.92 | R7: Rf​+β×ERP
B8: NOPAT | C8: =C6*(1-C7) -> 1627.7334 | D8: =D6*(1-D7) -> 1825.1136 | E8: =E6*(1-E7) -> 2025.2519 | F8: =F6*(1-F7) -> 2223.8909 | G8: =G6*(1-G7) -> 2361.0592 | H8: =H6*(1-H7) -> 2508.4988 | I8: =I6*(1-I7) -> 2666.4706 | J8: =J6*(1-J7) -> 2835.3746 | N8: CAPM | Q8: =Q4+Q7*Q6 -> 0.1068
B9: Dep & Amor. | C9: =-PL!M13 -> 377.0129 | D9: =-PL!N13 -> 417.15874 | E9: =-PL!O13 -> 458.34414 | F9: =-PL!P13 -> 500.18378 | G9: =-PL!Q13 -> 542.54183 | H9: =-PL!R13 -> 585.84613 | I9: =-PL!S13 -> 630.7003 | J9: =-PL!T13 -> 677.58456 | N9: WACC | Q9: =Q8 -> 0.1068 | R9: Debt is almost negligible, therefore no impact on WACC
B10: Capex | C10: =-'Working Schedules'!H42 -> -203.83545 | D10: =-'Working Schedules'!I42 -> -222.18064 | E10: =-'Working Schedules'!J42 -> -239.95509 | F10: =-'Working Schedules'!K42 -> -256.75195 | G10: =-'Working Schedules'!L42 -> -273.44082 | H10: =-'Working Schedules'!M42 -> -291.21448 | I10: =-'Working Schedules'!N42 -> -310.14342 | J10: =-'Working Schedules'!O42 -> -330.30274
B11: Changes in NWC | C11: =-'Working Capital Schedule'!M21 -> -685.86951 | D11: =-'Working Capital Schedule'!N21 -> 124.64106 | E11: =-'Working Capital Schedule'!O21 -> -495.70166 | F11: =-'Working Capital Schedule'!P21 -> 138.54864 | G11: =-'Working Capital Schedule'!Q21 -> -527.54843 | H11: =-'Working Capital Schedule'!R21 -> 98.47563 | I11: =-'Working Capital Schedule'!S21 -> -553.82515 | J11: =-'Working Capital Schedule'!T21 -> 70.579636
B12: Free Cash Flow | C12: =SUM(C8:C11) -> 1115.0414 | D12: =SUM(D8:D11) -> 2144.7328 | E12: =SUM(E8:E11) -> 1747.9393 | F12: =SUM(F8:F11) -> 2605.8714 | G12: =SUM(G8:G11) -> 2102.6118 | H12: =SUM(H8:H11) -> 2901.606 | I12: =SUM(I8:I11) -> 2433.2023 | J12: =SUM(J8:J11) -> 3253.236
B13: Discount Period | C13: 1 | D13: =C13+1 -> 2 | E13: =D13+1 -> 3 | F13: =E13+1 -> 4 | G13: =F13+1 -> 5 | H13: =G13+1 -> 6 | I13: =H13+1 -> 7 | J13: =I13+1 -> 8
B15: PV of FCF | C15: =C12/(1+$Q$9)^C13 -> 1007.4461 | D15: =D12/(1+$Q$9)^D13 -> 1750.7933 | E15: =E12/(1+$Q$9)^E13 -> 1289.1959 | F15: =F12/(1+$Q$9)^F13 -> 1736.5063 | G15: =G12/(1+$Q$9)^G13 -> 1265.9406 | H15: =H12/(1+$Q$9)^H13 -> 1578.4235 | I15: =I12/(1+$Q$9)^I13 -> 1195.8981 | J15: =J12/(1+$Q$9)^J13 -> 1444.6491
N16: Sensitivity Analysis | U16: Horizontal axis | W16: WACC
U17: Vertical axis | W17: Terminal Growth
B18: Terminal Growth Rate (g) | C18: 0.06 | N18: =IF(C28<0,"",C28) -> 642.24 | O18: 0.08 | P18: =O18+0.5% -> 0.085 | Q18: =P18+0.5% -> 0.09 | R18: =Q18+0.5% -> 0.095 | S18: =R18+0.5% -> 0.1 | T18: 0.1068 | U18: 0.12 | V18: =U18+0.5% -> 0.125 | W18: =V18+0.5% -> 0.13
B19: Terminal Year FCF | C19: =J12 -> 3253.236 | N19: 0.05 | O19: 1056.569 | P19: 905.78038 | Q19: 792.81642 | R19: 705.06463 | S19: 634.9577 | T19: 559.5479 | U19: 455.30914 | V19: 425.50339 | W19: 399.4706
B20: Terminal Value | C20: =C19*(1+C18)/(Q9-C18) -> 73684.406 | N20: =N19+0.5% -> 0.055 | O20: 1230.5431 | P20: 1026.094 | Q20: 880.19375 | R20: 770.88207 | S20: 685.95897 | T20: 596.90302 | U20: 477.54094 | V20: 444.17945 | W20: 415.31267
B21: PV of Terminal Value | C21: =C20/(1+Q9)^J13 -> 32720.685 | N21: =N20+0.5% -> 0.06 | O21: 1491.5044 | P21: 1194.5331 | Q21: 996.69685 | R21: 855.50448 | S21: 749.71055 | T21: 642.24 | U21: 503.47805 | V21: 465.72876 | W21: 433.4179
B22: Sum of OV of FCF | C22: =SUM(C15:J15) -> 11268.853 | N22: =N21+0.5% -> 0.065 | O22: 1926.4397 | P22: 1447.1917 | Q22: 1159.8012 | R22: 968.33437 | S22: 831.67687 | T22: 698.42315 | U22: 534.13099 | V22: 490.86961 | W22: 454.30854
B23: Enterprise Value | C23: =C21+C22 -> 43989.538 | N23: =N22+0.5% -> 0.07 | O23: 2796.3105 | P23: 1868.2894 | Q23: 1404.4577 | R23: 1126.2962 | S23: 940.9653 | T23: 769.87346 | U23: 570.91452 | V23: 520.58153 | W23: 478.68095
B24: Cash | C24: =BS!L43 -> 3134 | N24: =N23+0.5% -> 0.075 | O24: 5405.9228 | P24: 2710.4848 | Q24: 1812.2186 | R24: 1363.239 | S24: 1093.9691 | T24: 863.79243 | U24: 615.87217 | V24: 556.23583 | W24: 507.48472
B25: Debt | C25: =-BS!L15 -> -407 | N25: =N24+0.5% -> 0.08 | P25: 5237.0709 | Q25: 2627.7403 | R25: 1758.1436 | S25: 1323.4748 | T25: 992.75578 | U25: 672.06924 | V25: 599.81331 | W25: 542.04923
B26: Equity Value | C26: =SUM(C23:C25) -> 46716.538 | N26: =N25+0.5% -> 0.085 | Q26: 5074.3055 | R26: 2547.9528 | S26: 1705.9843 | T26: 1180.8766 | U26: 744.3226 | V26: 654.28516 | W26: 584.29475
B27: Shares Outstanding | C27: 72.74 | N27: =N26+0.5% -> 0.09 | R27: 4917.3804 | S27: 2471.0033 | T27: 1480.9742 | U27: 840.66042 | V27: 724.32039 | W27: 637.10165
B28: Per Share Value | C28: =C26/C27 -> 642.24

Sheet Ratio Analysis
B2: Ratio Analysis
B4: Particulars | C4: 2017 | D4: =C4+1 -> 2018 | E4: =D4+1 -> 2019 | F4: =E4+1 -> 2020 | G4: =F4+1 -> 2021 | H4: =G4+1 -> 2022 | I4: =H4+1 -> 2023 | J4: =I4+1 -> 2024 | K4: =J4+1 -> 2025 | ... T4: =S4+1 -> 2034
B6: Profitability Ratios
B7: Gross Margin | C7: =PL!C7/PL!C5 -> 0.41578679 | D7: =PL!D7/PL!D5 -> 0.46950155 | E7: =PL!E7/PL!E5 -> 0.46831107 | F7: =PL!F7/PL!F5 -> 0.42415339 | G7: =PL!G7/PL!G5 -> 0.40876613 | H7: =PL!H7/PL!H5 -> 0.41508793 | I7: =PL!I7/PL!I5 -> 0.38720317 | J7: =PL!J7/PL!J5 -> 0.42213585 | ... T7: =PL!T7/PL!T5 -> 0.47
B8: EBITDA Margin | C8: =PL!C12/PL!C5 -> 0.1124355 | D8: =PL!D12/PL!D5 -> 0.1407585 | E8: =PL!E12/PL!E5 -> 0.14921634 | F8: =PL!F12/PL!F5 -> 0.16846462 | G8: =PL!G12/PL!G5 -> 0.12930282 | H8: =PL!H12/PL!H5 -> 0.16424365 | I8: =PL!I12/PL!I5 -> 0.13352808 | J8: =PL!J12/PL!J5 -> 0.17666284 | ... T8: =PL!T12/PL!T5 -> 0.20245445
B9: EBIT Margin | C9: =PL!C14/PL!C5 -> 0.091046215 | D9: =PL!D14/PL!D5 -> 0.11837357 | E9: =PL!E14/PL!E5 -> 0.12623116 | F9: =PL!F14/PL!F5 -> 0.13787076 | G9: =PL!G14/PL!G5 -> 0.092519031 | H9: =PL!H14/PL!H5 -> 0.13296405 | I9: =PL!I14/PL!I5 -> 0.10686016 | J9: =PL!J14/PL!J5 -> 0.1523717 | ... T9: =PL!T14/PL!T5 -> 0.17168338
B10: Net Profit Margin | C10: =PL!C22/PL!C5 -> 0.010547207 | D10: =PL!D22/PL!D5 -> 0.07588527 | E10: =PL!E22/PL!E5 -> 0.07318431 | F10: =PL!F22/PL!F5 -> 0.066549424 | G10: =PL!G22/PL!G5 -> 0.044531625 | H10: =PL!H22/PL!H5 -> 0.083460319 | I10: =PL!I22/PL!I5 -> 0.10608745 | J10: =PL!J22/PL!J5 -> 0.12437064 | ... T10: =PL!T22/PL!T5 -> 0.1368565
B11: Retrun on Equity (ROE) | C11: =PL!C22/(AVERAGE(BS!C10,1634)) -> 0.054392327 | D11: =PL!D22/AVERAGE(BS!C10,BS!D10) -> 0.31008158 | E11: =PL!E22/AVERAGE(BS!D10,BS!E10) -> 0.24815769 | F11: =PL!F22/AVERAGE(BS!E10,BS!F10) -> 0.18203951 | G11: =PL!G22/AVERAGE(BS!F10,BS!G10) -> 0.092280639 | H11: =PL!H22/AVERAGE(BS!G10,BS!H10) -> 0.17867416 | I11: =PL!I22/AVERAGE(BS!H10,BS!I10) -> 0.2055655 | J11: =PL!J22/AVERAGE(BS!I10,BS!J10) -> 0.21462597 | K11: =PL!K22/AVERAGE(BS!J10,BS!K10) -> 0.20781609 | ... T11: =PL!T22/AVERAGE(BS!S10,BS!T10) -> 0.20457278
B12: Return on Capital Employed (ROCE) | C12: =PL!C14/(BS!C46-BS!C23) -> 0.30080935 | D12: =PL!D14/(BS!D46-BS!D23) -> 0.31888739 | E12: =PL!E14/(BS!E46-BS!E23) -> 0.30275253 | F12: =PL!F14/(BS!F46-BS!F23) -> 0.32575758 | G12: =PL!G14/(BS!G46-BS!G23) -> 0.17471376 | H12: =PL!H14/(BS!H46-BS!H23) -> 0.24519632 | I12: =PL!I14/(BS!I46-BS!I23) -> 0.18210139 | J12: =PL!J14/(BS!J46-BS!J23) -> 0.23202948 | ... T12: =PL!T14/(BS!T46-BS!T23) -> 0.2198676
B13: Liquidity Ratios
B14: Current Ratio | C14: =BS!C44/BS!C23 -> 0.92323875 | D14: =BS!D44/BS!D23 -> 0.99459028 | E14: =BS!E44/BS!E23 -> 1.0094931 | F14: =BS!F44/BS!F23 -> 0.99302681 | G14: =BS!G44/BS!G23 -> 1.1351658 | H14: =BS!H44/BS!H23 -> 1.416765 | I14: =BS!I44/BS!I23 -> 1.7640767 | J14: =BS!J44/BS!J23 -> 1.9338856 | ... T14: =BS!T44/BS!T23 -> 2.4776957
B15: Quick Ratio | C15: =(BS!C44-BS!C41)/BS!C23 -> 0.61368855 | D15: =(BS!D44-BS!D41)/BS!D23 -> 0.66173666 | E15: =(BS!E44-BS!E41)/BS!E23 -> 0.6385325 | F15: =(BS!F44-BS!F41)/BS!F23 -> 0.60002039 | G15: =(BS!G44-BS!G41)/BS!G23 -> 0.65020917 | H15: =(BS!H44-BS!H41)/BS!H23 -> 0.82499657 | I15: =(BS!I44-BS!I41)/BS!I23 -> 1.1330994 | J15: =(BS!J44-BS!J41)/BS!J23 -> 1.3930687 | ... T15: =(BS!T44-BS!T41)/BS!T23 -> 1.9366092
B16: Leverage Ratios
B17: Debt Equity Ratio | C17: =(BS!C16+BS!C20)/BS!C10 -> 2.1225918 | D17: =(BS!D16+BS!D20)/BS!D10 -> 1.2695217 | E17: =(BS!E16+BS!E20)/BS!E10 -> 0.93638158 | F17: =(BS!F16+BS!F20)/BS!F10 -> 0.48948498 | G17: =(BS!G16+BS!G20)/BS!G10 -> 0.25743968 | H17: =(BS!H16+BS!H20)/BS!H10 -> 0.13200234 | I17: =(BS!I16+BS!I20)/BS!I10 -> 0.038103175 | J17: =(BS!J16+BS!J20)/BS!J10 -> 0.047521416 | ... T17: =(BS!T16+BS!T20)/BS!T10 -> 0.12949303
B18: Net debt to EBITDA | C18: =(BS!C13+BS!C15-BS!C43)/PL!C12 -> 0.80280412 | D18: =(BS!D13+BS!D15-BS!D43)/PL!D12 -> 0.42482633 | E18: =(BS!E13+BS!E15-BS!E43)/PL!E12 -> 0.37408523 | F18: =(BS!F13+BS!F15-BS!F43)/PL!F12 -> 0.087651178 | G18: =(BS!G13+BS!G15-BS!G43)/PL!G12 -> 0.072379684 | H18: =(BS!H13+BS!H15-BS!H43)/PL!H12 -> -0.011033099 | I18: =(BS!I13+BS!I15-BS!I43)/PL!I12 -> -0.67494707 | J18: =(BS!J13+BS!J15-BS!J43)/PL!J12 -> -0.8138 | ... T18: =(BS!T13+BS!T15-BS!T43)/PL!T12 -> -1.3708795
B19: Interest Coverage Ratio | C19: =PL!C14/-PL!C17 -> 2.1402293 | D19: =PL!D14/-PL!D17 -> 3.6645045 | E19: =PL!E14/-PL!E17 -> 4.9709106 | F19: =PL!F14/-PL!F17 -> 6.0646226 | G19: =PL!G14/-PL!G17 -> 4.0101279 | H19: =PL!H14/-PL!H17 -> 14.675 | I19: =PL!I14/-PL!I17 -> 10.903846 | J19: =PL!J14/-PL!J17 -> 22.697368 | ... T19: =PL!T14/-PL!T17 -> 17.959221
B20: Efficiency Ratios
B21: Asset Turnover Ratio | C21: =PL!C5/(AVERAGE(7889,BS!C46)) -> 1.0506467 | D21: =PL!D5/AVERAGE(BS!C46,BS!D46) -> 0.9624136 | E21: =PL!E5/AVERAGE(BS!D46,BS!E46) -> 1.0341209 | F21: =PL!F5/AVERAGE(BS!E46,BS!F46) -> 1.0384517 | G21: =PL!G5/AVERAGE(BS!F46,BS!G46) -> 0.93526107 | H21: =PL!H5/AVERAGE(BS!G46,BS!H46) -> 1.1132775 | I21: =PL!I5/AVERAGE(BS!H46,BS!I46) -> 1.1366265 | J21: =PL!J5/AVERAGE(BS!I46,BS!J46) -> 1.0776517 | K21: =PL!K5/AVERAGE(BS!J46,BS!K46) -> 0.98534514 | ... T21: =PL!T5/AVERAGE(BS!S46,BS!T46) -> 0.90748513
B22: Fixed Asset Turnover Ratio | C22: =PL!C5/AVERAGE(1887,BS!C35) -> 4.405556 | D22: =PL!D5/AVERAGE(BS!C35,BS!D35) -> 4.2362049 | E22: =PL!E5/AVERAGE(BS!D35,BS!E35) -> 4.8698191 | F22: =PL!F5/AVERAGE(BS!E35,BS!F35) -> 4.7142027 | G22: =PL!G5/AVERAGE(BS!F35,BS!G35) -> 4.0314832 | H22: =PL!H5/AVERAGE(BS!G35,BS!H35) -> 4.9598611 | I22: =PL!I5/AVERAGE(BS!H35,BS!I35) -> 6.0331448 | J22: =PL!J5/AVERAGE(BS!I35,BS!J35) -> 7.465216 | K22: =PL!K5/AVERAGE(BS!J35,BS!K35) -> 7.6236498 | ... T22: =PL!T5/AVERAGE(BS!S35,BS!T35) -> 7.2790275
B23: Working Capital Ratios
B24: Receivables days | C24: =AVERAGE(2303,BS!C40)*365/PL!C5 -> 108.79422 | D24: =AVERAGE(BS!C40,BS!D40)*365/PL!D5 -> 120.33962 | E24: =AVERAGE(BS!D40,BS!E40)*365/PL!E5 -> 102.64648 | F24: =AVERAGE(BS!E40,BS!F40)*365/PL!F5 -> 94.445815 | G24: =AVERAGE(BS!F40,BS!G40)*365/PL!G5 -> 100.341 | H24: =AVERAGE(BS!G40,BS!H40)*365/PL!H5 -> 85.699312 | I24: =AVERAGE(BS!H40,BS!I40)*365/PL!I5 -> 82.67876 | J24: =AVERAGE(BS!I40,BS!J40)*365/PL!J5 -> 88.501457 | K24: =AVERAGE(BS!J40,BS!K40)*365/PL!K5 -> 97.774878 | ... T24: =AVERAGE(BS!S40,BS!T40)*365/PL!T5 -> 97
B25: Payables days | C25: =AVERAGE(1019,BS!C19)*365/-PL!C6 -> 79.489692 | D25: =AVERAGE(BS!C19,BS!D19)*365/-PL!D6 -> 107.31431 | E25: =AVERAGE(BS!D19,BS!E19)*365/-PL!E6 -> 105.22119 | F25: =AVERAGE(BS!E19,BS!F19)*365/-PL!F6 -> 88.622952 | G25: =AVERAGE(BS!F19,BS!G19)*365/-PL!G6 -> 99.330109 | H25: =AVERAGE(BS!G19,BS!H19)*365/-PL!H6 -> 96.353087 | I25: =AVERAGE(BS!H19,BS!I19)*365/-PL!I6 -> 94.424035 | J25: =AVERAGE(BS!I19,BS!J19)*365/-PL!J6 -> 104.2359 | K25: =AVERAGE(BS!J19,BS!K19)*365/-PL!K6 -> 111.54847 | ... T25: =AVERAGE(BS!S19,BS!T19)*365/-PL!T6 -> 104
B26: Inventory days | C26: =AVERAGE(1952,BS!C41)*365/-PL!C6 -> 137.44628 | D26: =AVERAGE(BS!C41,BS!D41)*365/-PL!D6 -> 154.06759 | E26: =AVERAGE(BS!D41,BS!E41)*365/-PL!E6 -> 141.6227 | F26: =AVERAGE(BS!E41,BS!F41)*365/-PL!F6 -> 131.24367 | G26: =AVERAGE(BS!F41,BS!G41)*365/-PL!G6 -> 151.06407 | H26: =AVERAGE(BS!G41,BS!H41)*365/-PL!H6 -> 135.20208 | I26: =AVERAGE(BS!H41,BS!I41)*365/-PL!I6 -> 123.10822 | J26: =AVERAGE(BS!I41,BS!J41)*365/-PL!J6 -> 119.76039 | K26: =AVERAGE(BS!J41,BS!K41)*365/-PL!K6 -> 116.20408 | ... T26: =AVERAGE(BS!S41,BS!T41)*365/-PL!T6 -> 135
B27: Valuation Ratios
B28: EV/EBITDA | C28: =C37/PL!C12 -> 32.645814 | D28: =D37/PL!D12 -> 38.021998 | E28: =E37/PL!E12 -> 28.555747 | F28: =F37/PL!F12 -> 22.775493 | G28: =G37/PL!G12 -> 36.048031 | H28: =H37/PL!H12 -> 39.341161 | I28: =I37/PL!I12 -> 39.211418 | J28: =J37/PL!J12 -> 40.21156 | ... T28: =T37/PL!T12 -> 21.023884
B29: EV/Sales | C29: =C37/PL!C5 -> 3.6705483 | D29: =D37/PL!D5 -> 5.3519195 | E29: =E37/PL!E5 -> 4.2609841 | F29: =F37/PL!F5 -> 3.8368649 | G29: =G37/PL!G5 -> 4.661112 | H29: =H37/PL!H5 -> 6.4615358 | I29: =I37/PL!I5 -> 5.2358255 | J29: =J37/PL!J5 -> 7.1038883 | ... T29: =T37/PL!T5 -> 4.2563788
B30: EV/EBIT | C30: =C37/PL!C14 -> 40.315222 | D30: =D37/PL!D14 -> 45.212115 | E30: =E37/PL!E14 -> 33.755407 | F30: =F37/PL!F14 -> 27.829431 | G30: =G37/PL!G14 -> 50.380035 | H30: =H37/PL!H14 -> 48.596113 | I30: =I37/PL!I14 -> 48.996984 | J30: =J37/PL!J14 -> 46.622099 | ... T30: =T37/PL!T14 -> 24.792026
B31: PE Ratio | C31: =C34/PL!C22 -> 339.45333 | D31: =D34/PL!D22 -> 69.738457 | E31: =E34/PL!E22 -> 57.459918 | F31: =F34/PL!F22 -> 57.432485 | G31: =G34/PL!G22 -> 104.45954 | H31: =H34/PL!H22 -> 77.442166 | I31: =I34/PL!I22 -> 50.203393 | J31: =J34/PL!J22 -> 58.274659 | ... T31: =T34/PL!T22 -> 32.005933
B34: Market Cap | C34: =C35*C36 -> 31569.16 | D34: =D35*D36 -> 45462.5 | E34: =E35*E36 -> 39279.6 | F34: =F35*F36 -> 35642.6 | G34: =G35*G36 -> 37824.8 | H34: =H35*H36 -> 62774.62 | I34: =I35*I36 -> 56518.98 | J34: =J35*J36 -> 82050.72 | ... L34: =L35*L36 -> 96453.24 | M34: =L34 -> 96453.24 | N34: =M34 -> 96453.24 | O34: =N34 -> 96453.24 | P34: =O34 -> 96453.24 | Q34: =P34 -> 96453.24 | R34: =Q34 -> 96453.24 | S34: =R34 -> 96453.24 | T34: =S34 -> 96453.24
B35: CMP | C35: 434 | D35: 625 | E35: 540 | F35: 490 | G35: 520 | H35: 863 | I35: 777 | J35: 1128 | K35: 1427 | L35: 1326
B36: Shares outstanding | C36: 72.74 | D36: 72.74 | E36: 72.74 | F36: 72.74 | G36: 72.74 | H36: 72.74 | I36: 72.74 | J36: 72.74 | K36: 72.74 | L36: 72.74 | M36: 72.74 | N36: 72.74 | O36: 72.74 | P36: 72.74 | Q36: 72.74 | R36: 72.74 | S36: 72.74 | T36: 72.74
B37: EV | C37: =C34+BS!C13+BS!C15-BS!C43 -> 32365.06 | D37: =D34+BS!D13+BS!D15-BS!D43 -> 45976.2 | E37: =E34+BS!E13+BS!E15-BS!E43 -> 39801 | F37: =F34+BS!F13+BS!F15-BS!F43 -> 35780.3 | G37: =G34+BS!G13+BS!G15-BS!G43 -> 37900.9 | H37: =H34+BS!H13+BS!H15-BS!H43 -> 62757.02 | I37: =I34+BS!I13+BS!I15-BS!I43 -> 55562.58 | J37: =J34+BS!J13+BS!J15-BS!J43 -> 80423.12 | ... L37: =L34+BS!L13+BS!L15-BS!L43 -> 93726.24 | M37: =L37 -> 93726.24 | N37: =M37 -> 93726.24 | O37: =N37 -> 93726.24 | P37: =O37 -> 93726.24 | Q37: =P37 -> 93726.24 | R37: =Q37 -> 93726.24 | S37: =R37 -> 93726.24 | T37: =S37 -> 93726.24

Sheet PL
B2: Income Statement | T2: ="CURRENTLY RUNNING: "&UPPER(CHOOSE(Scenarios!$D$4,Scenarios!C12,Scenarios!C13,Scenarios!C14))&" SCENARIO" -> CURRENTLY RUNNING: BASE SCENARIO
A4: x | B4: Particulars | C4: 2017 | D4: =C4+1 -> 2018 | E4: =D4+1 -> 2019 | F4: =E4+1 -> 2020 | G4: =F4+1 -> 2021 | H4: =G4+1 -> 2022 | I4: =H4+1 -> 2023 | J4: =I4+1 -> 2024 | K4: =J4+1 -> 2025 | ... T4: =S4+1 -> 2034
B5: Sales | C5: 8817.5 | D5: 8590.6 | E5: 9340.8 | F5: 9325.4 | G5: 8131.3 | H5: 9712.4 | I5: 10612 | J5: 11321 | K5: 12069 | L5: 12467 | M5: =L5*(1+Scenarios!H10) -> 13589.03 | N5: =M5*(1+Scenarios!I10) -> 14812.043 | O5: =N5*(1+Scenarios!J10) -> 15997.006 | P5: =O5*(1+Scenarios!K10) -> 17116.797 | Q5: =P5*(1+Scenarios!L10) -> 18229.388 | R5: =Q5*(1+Scenarios!M10) -> 19414.299 | S5: =R5*(1+Scenarios!N10) -> 20676.228 | T5: =S5*(1+Scenarios!O10) -> 22020.183
B6: Total COGS | C6: -5151.3 | D6: -4557.3 | E6: -4966.4 | F6: -5370 | G6: -4807.5 | H6: -5680.9 | I6: -6503 | J6: -6542 | K6: -6860 | L6: -6674 | M6: =-M5*(1-Scenarios!H19) -> -7406.0213 | N6: =-N5*(1-Scenarios!I19) -> -7998.5031 | O6: =-O5*(1-Scenarios!J19) -> -8558.3983 | P6: =-P5*(1-Scenarios!K19) -> -9071.9022 | Q6: =-Q5*(1-Scenarios!L19) -> -9661.5758 | R6: =-R5*(1-Scenarios!M19) -> -10289.578 | S6: =-S5*(1-Scenarios!N19) -> -10958.401 | T6: =-T5*(1-Scenarios!O19) -> -11670.697
A7: x | B7: Gross Profit | C7: =C5+C6 -> 3666.2 | D7: =D5+D6 -> 4033.3 | E7: =E5+E6 -> 4374.4 | F7: =F5+F6 -> 3955.4 | G7: =G5+G6 -> 3323.8 | H7: =H5+H6 -> 4031.5 | I7: =I5+I6 -> 4109 | J7: =J5+J6 -> 4779 | ... T7: =T5+T6 -> 10349.486
B8: Operating Expenes
B9: Employee Cost | C9: -688.9 | D9: -681.2 | E9: -690.2 | F9: -530.4 | G9: -557 | H9: -653.9 | I9: -613 | J9: -549 | K9: -614 | L9: -635 | M9: =-M5*Assumptions!E7 -> -849.93335 | N9: =-N5*Assumptions!F7 -> -926.42735 | O9: =-O5*Assumptions!G7 -> -1000.5415 | P9: =-P5*Assumptions!H7 -> -1070.5794 | Q9: =-Q5*Assumptions!I7 -> -1140.1671 | R9: =-R5*Assumptions!J7 -> -1214.278 | S9: =-S5*Assumptions!K7 -> -1293.206 | T9: =-T5*Assumptions!L7 -> -1377.2644
B10: Selling and admin | C10: -1985.9 | D10: -2142.9 | E10: -2290.4 | F10: -1854 | G10: -1715.4 | H10: -1782.4 | I10: -2079 | J10: -2230 | K10: -2359 | L10: -2879 | M10: =-M5*Assumptions!E8 -> -2785.7512 | N10: =-N5*Assumptions!F8 -> -3036.4688 | O10: =-O5*Assumptions!G8 -> -3279.3863 | P10: =-P5*Assumptions!H8 -> -3508.9433 | Q10: =-Q5*Assumptions!I8 -> -3737.0246 | R10: =-R5*Assumptions!J8 -> -3979.9312 | S10: =-S5*Assumptions!K8 -> -4238.6267 | T10: =-T5*Assumptions!L8 -> -4514.1375
B11: Total Operating Expenses | C11: =SUM(C9:C10) -> -2674.8 | D11: =SUM(D9:D10) -> -2824.1 | E11: =SUM(E9:E10) -> -2980.6 | F11: =SUM(F9:F10) -> -2384.4 | G11: =SUM(G9:G10) -> -2272.4 | H11: =SUM(H9:H10) -> -2436.3 | I11: =SUM(I9:I10) -> -2692 | J11: =SUM(J9:J10) -> -2779 | ... T11: =SUM(T9:T10) -> -5891.4019
A12: x | B12: EBITDA | C12: =C7+C11 -> 991.4 | D12: =D7+D11 -> 1209.2 | E12: =E7+E11 -> 1393.8 | F12: =F7+F11 -> 1571 | G12: =G7+G11 -> 1051.4 | H12: =H7+H11 -> 1595.2 | I12: =I7+I11 -> 1417 | J12: =J7+J11 -> 2000 | ... T12: =T7+T11 -> 4458.084
B13: Depreciation & Amortization | C13: -188.6 | D13: -192.3 | E13: -214.7 | F13: -285.3 | G13: -299.1 | H13: -303.8 | I13: -283 | J13: -275 | K13: -283 | L13: -289 | M13: ='Working Schedules'!H70 -> -377.0129 | N13: ='Working Schedules'!I70 -> -417.15874 | O13: ='Working Schedules'!J70 -> -458.34414 | P13: ='Working Schedules'!K70 -> -500.18378 | Q13: ='Working Schedules'!L70 -> -542.54183 | R13: ='Working Schedules'!M70 -> -585.84613 | S13: ='Working Schedules'!N70 -> -630.7003 | T13: ='Working Schedules'!O70 -> -677.58456
B14: EBIT | C14: =C12+C13 -> 802.8 | D14: =D12+D13 -> 1016.9 | E14: =E12+E13 -> 1179.1 | F14: =F12+F13 -> 1285.7 | G14: =G12+G13 -> 752.3 | H14: =H12+H13 -> 1291.4 | I14: =I12+I13 -> 1134 | J14: =J12+J13 -> 1725 | ... T14: =T12+T13 -> 3780.4994
B15: Other Income(Inc Interest) | C15: 105.3 | D15: 218.9 | E15: 69.2 | F15: 22 | G15: 39.6 | H15: 35.5 | I15: 73.1 | J15: 225 | K15: 336 | L15: 478 | M15: 0 | N15: 0 | O15: 0 | P15: 0 | Q15: 0 | R15: 0 | S15: 0 | T15: 0
B16: Exceptional Items | C16: -368.1 | D16: -44.5 | E16: 2.6 | F16: 66.6 | G16: -64.3 | H16: -165.2 | I16: 176.4 | J16: -17 | K16: -65 | L16: 38 | M16: 0 | N16: 0 | O16: 0 | P16: 0 | Q16: 0 | R16: 0 | S16: 0 | T16: 0
B17: Interest Paid | C17: -375.1 | D17: -277.5 | E17: -237.2 | F17: -212 | G17: -187.6 | H17: -88 | I17: -104 | J17: -76 | K17: -89 | L17: -158 | M17: =-'Working Schedules'!H33 -> -95.837343 | N17: =-'Working Schedules'!I33 -> -108.83716 | O17: =-'Working Schedules'!J33 -> -123.13957 | P17: =-'Working Schedules'!K33 -> -138.58164 | Q17: =-'Working Schedules'!L33 -> -155.02463 | R17: =-'Working Schedules'!M33 -> -172.45339 | S17: =-'Working Schedules'!N33 -> -190.92618 | T17: =-'Working Schedules'!O33 -> -210.50465
B18: Interest Received | M18: =BS!L43*Assumptions!E9 -> 203.71 | N18: =BS!M43*Assumptions!F9 -> 197.0201 | O18: =BS!N43*Assumptions!G9 -> 247.64641 | P18: =BS!O43*Assumptions!H9 -> 263.59935 | Q18: =BS!P43*Assumptions!I9 -> 325.87271 | R18: =BS!Q43*Assumptions!J9 -> 349.33898 | S18: =BS!R43*Assumptions!K9 -> 417.49706 | T18: =BS!S43*Assumptions!L9 -> 448.14526
A19: x | B19: Profit Before Tax (PBT) | C19: =SUM(C14:C17) -> 164.9 | D19: =SUM(D14:D17) -> 913.8 | E19: =SUM(E14:E18) -> 1013.7 | F19: =SUM(F14:F18) -> 1162.3 | G19: =SUM(G14:G18) -> 540 | H19: =SUM(H14:H18) -> 1073.7 | I19: =SUM(I14:I18) -> 1279.5 | J19: =SUM(J14:J18) -> 1857 | K19: =SUM(K14:K18) -> 2135 | L19: =SUM(L14:L18) -> 2348 | ... T19: =SUM(T14:T18) -> 4018.1401
B20: Tax | C20: -69.7 | D20: -259.9 | E20: -328.1 | F20: -539.7 | G20: -177.9 | H20: -276 | I20: -153 | J20: -449 | K20: -553 | L20: -510 | M20: =-M19*Assumptions!E10 -> -569.54598 | N20: =-N19*Assumptions!F10 -> -630.41694 | O20: =-O19*Assumptions!G10 -> -706.21069 | P20: =-P19*Assumptions!H10 -> -772.55139 | Q20: =-Q19*Assumptions!I10 -> -829.73176 | R20: =-R19*Assumptions!J10 -> -880.38765 | S20: =-S19*Assumptions!K10 -> -945.46624 | T20: =-T19*Assumptions!L10 -> -1004.535
B21: Adjustments | C21: -2.2 | D21: -2 | E21: -2 | F21: -2 | G21: 0 | H21: 12.9 | I21: -0.7 | J21: 0 | K21: 0 | L21: 0 | M21: 0 | N21: 0 | O21: 0 | P21: 0 | Q21: 0 | R21: 0 | S21: 0 | T21: 0
A22: x | B22: Profit After Tax (PAT) | C22: =SUM(C19:C21) -> 93 | D22: =SUM(D19:D21) -> 651.9 | E22: =SUM(E19:E21) -> 683.6 | F22: =SUM(F19:F21) -> 620.6 | G22: =SUM(G19:G21) -> 362.1 | H22: =SUM(H19:H21) -> 810.6 | I22: =SUM(I19:I21) -> 1125.8 | J22: =SUM(J19:J21) -> 1408 | ... L22: =SUM(L19:L21) -> 1838 | M22: =M19+M20 -> 1708.6379 | N22: =N19+N20 -> 1891.2508 | O22: =O19+O20 -> 2118.6321 | P22: =P19+P20 -> 2317.6542 | Q22: =Q19+Q20 -> 2489.1953 | R22: =R19+R20 -> 2641.163 | S22: =S19+S20 -> 2836.3987 | T22: =T19+T20 -> 3013.605

Sheet BS
B2: Balance Sheet | T2: =PL!T2 -> CURRENTLY RUNNING: BASE SCENARIO
B4: Particulars | C4: 2017 | D4: =C4+1 -> 2018 | E4: =D4+1 -> 2019 | F4: =E4+1 -> 2020 | G4: =F4+1 -> 2021 | H4: =G4+1 -> 2022 | I4: =H4+1 -> 2023 | J4: =I4+1 -> 2024 | K4: =J4+1 -> 2025 | ... T4: =S4+1 -> 2034
A6: x | B6: Equities & Liablilities
B7: Shareholders' Fund
B8: Share Capital | C8: 145.3 | D8: 145.3 | E8: 145.3 | F8: 145.3 | G8: 145.3 | H8: 145.3 | I8: 145.5 | J8: 145 | K8: 145 | L8: 145 | M8: =L8 -> 145 | N8: =M8 -> 145 | O8: =N8 -> 145 | P8: =O8 -> 145 | Q8: =P8 -> 145 | R8: =Q8 -> 145 | S8: =R8 -> 145 | T8: =S8 -> 145
B9: Reserve & Surplus | C9: 1640.3 | D9: 2273.8 | E9: 2945 | F9: 3582.7 | G9: 3974.5 | H9: 4808.4 | I9: 5854 | J9: 6976 | K9: 7959 | L9: 8808 | M9: =L9+PL!M22*(1-Assumptions!E11) -> 9371.8505 | N9: =M9+PL!N22*(1-Assumptions!F11) -> 9995.9633 | O9: =N9+PL!O22*(1-Assumptions!G11) -> 10695.112 | P9: =O9+PL!P22*(1-Assumptions!H11) -> 11459.938 | Q9: =P9+PL!Q22*(1-Assumptions!I11) -> 12281.372 | R9: =Q9+PL!R22*(1-Assumptions!J11) -> 13152.956 | S9: =R9+PL!S22*(1-Assumptions!K11) -> 14088.968 | T9: =S9+PL!T22*(1-Assumptions!L11) -> 15083.457
B10: Total Shareholders' Fund | C10: =SUM(C8:C9) -> 1785.6 | D10: =SUM(D8:D9) -> 2419.1 | E10: =SUM(E8:E9) -> 3090.3 | F10: =SUM(F8:F9) -> 3728 | G10: =SUM(G8:G9) -> 4119.8 | H10: =SUM(H8:H9) -> 4953.7 | I10: =SUM(I8:I9) -> 5999.5 | J10: =SUM(J8:J9) -> 7121 | ... T10: =SUM(T8:T9) -> 15228.457
A12: x | B12: Non-Current Liabilities
B13: Long Term Borrowings | C13: 869.7 | D13: 762.8 | E13: 780.4 | F13: 14.7 | G13: 2.2 | H13: 0.9 | I13: 0.3 | J13: 0 | K13: 0 | L13: 0 | M13: =L13 -> 0 | N13: =M13 -> 0 | O13: =N13 -> 0 | P13: =O13 -> 0 | Q13: =P13 -> 0 | R13: =Q13 -> 0 | S13: =R13 -> 0 | T13: =S13 -> 0
B14: Deferred Tax Liabilities [Net] | C14: 0 | D14: 0 | E14: 0 | F14: 7.6 | G14: 26.1 | H14: 48.3 | I14: 45.1 | J14: 73 | K14: 72 | L14: 18 | M14: =L14 -> 18 | N14: =M14 -> 18 | O14: =N14 -> 18 | P14: =O14 -> 18 | Q14: =P14 -> 18 | R14: =Q14 -> 18 | S14: =R14 -> 18 | T14: =S14 -> 18
B15: Lease Liabilities | C15: 13.5 | D15: 7 | E15: 23.9 | F15: 196.5 | G15: 157.8 | H15: 263.9 | I15: 182.4 | J15: 240.4 | K15: 480 | L15: 407 | M15: ='Working Schedules'!H22 -> 552.87866 | N15: ='Working Schedules'!I22 -> 713.878 | O15: ='Working Schedules'!J22 -> 889.40594 | P15: ='Working Schedules'!K22 -> 1077.2208 | Q15: ='Working Schedules'!L22 -> 1276.2999 | R15: ='Working Schedules'!M22 -> 1487.3093 | S15: ='Working Schedules'!N22 -> 1710.9538 | T15: ='Working Schedules'!O22 -> 1947.979
B16: Total Non-Current Liabilities | C16: =SUM(C13:C15) -> 883.2 | D16: =SUM(D13:D15) -> 769.8 | E16: =SUM(E13:E15) -> 804.3 | F16: =SUM(F13:F15) -> 218.8 | G16: =SUM(G13:G15) -> 186.1 | H16: =SUM(H13:H15) -> 313.1 | I16: =SUM(I13:I15) -> 227.8 | J16: =SUM(J13:J15) -> 313.4 | ... T16: =SUM(T13:T15) -> 1965.979
A18: x | B18: Current Liabilities
B19: Trade Payables | C19: 1224.7 | D19: 1455.1 | E19: 1408.3 | F19: 1199.4 | G19: 1417.2 | H19: 1582.1 | I19: 1782.5 | J19: 1954 | K19: 2239 | L19: 2383 | M19: ='Working Capital Schedule'!M15 -> 1837.4176 | N19: ='Working Capital Schedule'!N15 -> 2720.6334 | O19: ='Working Capital Schedule'!O15 -> 2156.4812 | P19: ='Working Capital Schedule'!P15 -> 3013.2603 | Q19: ='Working Capital Schedule'!Q15 -> 2492.5144 | R19: ='Working Capital Schedule'!R15 -> 3371.1356 | S19: ='Working Capital Schedule'!S15 -> 2873.6517 | T19: ='Working Capital Schedule'!T15 -> 3777.0468
B20: Short Term Borrowings | C20: 2906.9 | D20: 2301.3 | E20: 2089.4 | F20: 1606 | G20: 874.5 | H20: 340.8 | I20: 0.8 | J20: 25 | K20: 0 | L20: 6 | M20: =L20 -> 6 | N20: =M20 -> 6 | O20: =N20 -> 6 | P20: =O20 -> 6 | Q20: =P20 -> 6 | R20: =Q20 -> 6 | S20: =R20 -> 6 | T20: =S20 -> 6
B21: ST Provisions | C21: 319.4 | D21: 361.9 | E21: 399.2 | F21: 462.1 | G21: 583.4 | H21: 502.9 | I21: 385.4 | J21: 383 | K21: 391 | L21: 541 | M21: =Assumptions!E23*PL!M5 -> 597.91732 | N21: =Assumptions!F23*PL!N5 -> 651.72988 | O21: =Assumptions!G23*PL!O5 -> 703.86827 | P21: =Assumptions!H23*PL!P5 -> 753.13905 | Q21: =Assumptions!I23*PL!Q5 -> 802.09309 | R21: =Assumptions!J23*PL!R5 -> 854.22914 | S21: =Assumptions!K23*PL!S5 -> 909.75403 | T21: =Assumptions!L23*PL!T5 -> 968.88804
B22: Other Current Liabilities | C22: 1776.1 | D22: 1649.1 | E22: 1317.4 | F22: 1637 | G22: 1356 | H22: 1218.7 | I22: 1365.5 | J22: 1452.6 | K22: 1962 | L22: 2161 | M22: =Assumptions!E24*PL!M5 -> 2174.2448 | N22: =Assumptions!F24*PL!N5 -> 2369.9268 | O22: =Assumptions!G24*PL!O5 -> 2559.521 | P22: =Assumptions!H24*PL!P5 -> 2738.6874 | Q22: =Assumptions!I24*PL!Q5 -> 2916.7021 | R22: =Assumptions!J24*PL!R5 -> 3106.2878 | S22: =Assumptions!K24*PL!S5 -> 3308.1965 | T22: =Assumptions!L24*PL!T5 -> 3523.2292
B23: Total Current Liabilities | C23: =SUM(C19:C22) -> 6227.1 | D23: =SUM(D19:D22) -> 5767.4 | E23: =SUM(E19:E22) -> 5214.3 | F23: =SUM(F19:F22) -> 4904.5 | G23: =SUM(G19:G22) -> 4231.1 | H23: =SUM(H19:H22) -> 3644.5 | I23: =SUM(I19:I22) -> 3534.2 | J23: =SUM(J19:J22) -> 3814.6 | ... T23: =SUM(T19:T22) -> 8275.1641
A25: x | B25: Total Equity & Liabilities | C25: =C10+C16+C23 -> 8895.9 | D25: =D10+D16+D23 -> 8956.3 | E25: =E10+E16+E23 -> 9108.9 | F25: =F10+F16+F23 -> 8851.3 | G25: =G10+G16+G23 -> 8537 | H25: =H10+H16+H23 -> 8911.3 | I25: =I10+I16+I23 -> 9761.5 | J25: =J10+J16+J23 -> 11249 | ... T25: =T10+T16+T23 -> 25469.6
B27: Assets
B28: Non-Current Assets
B29: Fixed Assets
B30: Property Plant & Equip | C30: 1455.4 | D30: 1418.2 | E30: 1371.4 | F30: 1353.8 | G30: 1324.7 | H30: 1215.2 | I30: 978.3 | J30: 844 | K30: 850 | L30: 1215 | M30: ='Working Schedules'!H67 -> 1261.5435 | N30: ='Working Schedules'!I67 -> 1312.2487 | O30: ='Working Schedules'!J67 -> 1365.5459 | P30: ='Working Schedules'!K67 -> 1419.5431 | Q30: ='Working Schedules'!L67 -> 1473.1658 | R30: ='Working Schedules'!M67 -> 1526.3897 | S30: ='Working Schedules'!N67 -> 1579.189 | T30: ='Working Schedules'!O67 -> 1631.5359
B31: Capital Work in Progress | C31: 199.3 | D31: 101.8 | E31: 101.9 | F31: 104.1 | G31: 88.3 | H31: 87.7 | I31: 66.8 | J31: 37 | K31: 72 | L31: 77 | M31: ='Working Schedules'!H44 -> 77 | N31: ='Working Schedules'!I44 -> 77 | O31: ='Working Schedules'!J44 -> 77 | P31: ='Working Schedules'!K44 -> 77 | Q31: ='Working Schedules'!L44 -> 77 | R31: ='Working Schedules'!M44 -> 77 | S31: ='Working Schedules'!N44 -> 77 | T31: ='Working Schedules'!O44 -> 77
B32: ROU Assets | F32: 197.5 | G32: 164.4 | H32: 260.6 | I32: 172.6 | J32: 226.6 | K32: 456.6 | L32: 500.49 | M32: ='Working Schedules'!H55 -> 671.22666 | N32: ='Working Schedules'!I55 -> 746.84386 | O32: ='Working Schedules'!J55 -> 821.93472 | P32: ='Working Schedules'!K55 -> 895.4384 | Q32: ='Working Schedules'!L55 -> 967.69644 | R32: ='Working Schedules'!M55 -> 1040.4349 | S32: ='Working Schedules'!N55 -> 1114.9499 | T32: ='Working Schedules'!O55 -> 1192.2423
B33: Intangible Assets | C33: 393.2 | D33: 383.8 | E33: 373.7 | F33: 383.6 | G33: 375.5 | H33: 358 | I33: 356.7 | J33: 349 | K33: 329 | L33: 76 | M33: ='Working Schedules'!H81 -> 95.48503 | N33: ='Working Schedules'!I81 -> 100.04951 | O33: ='Working Schedules'!J81 -> 105.20647 | P33: ='Working Schedules'!K81 -> 110.84335 | Q33: ='Working Schedules'!L81 -> 116.90814 | R33: ='Working Schedules'!M81 -> 123.42867 | S33: ='Working Schedules'!N81 -> 130.43455 | T33: ='Working Schedules'!O81 -> 137.95735
B34: Goodwill | C34: 68 | D34: 36.1 | E34: 49.3 | F34: 21 | G34: 21 | H34: 21 | I34: 1 | J34: 1 | K34: 1 | L34: 55 | M34: =L34 -> 55 | N34: =M34 -> 55 | O34: =N34 -> 55 | P34: =O34 -> 55 | Q34: =P34 -> 55 | R34: =Q34 -> 55 | S34: =R34 -> 55 | T34: =S34 -> 55
B35: Total Fixed Assets | C35: =SUM(C30:C34) -> 2115.9 | D35: =SUM(D30:D34) -> 1939.9 | E35: =SUM(E30:E34) -> 1896.3 | F35: =SUM(F30:F34) -> 2060 | G35: =SUM(G30:G34) -> 1973.9 | H35: =SUM(H30:H34) -> 1942.5 | I35: =SUM(I30:I34) -> 1575.4 | J35: =SUM(J30:J34) -> 1457.6 | ... T35: =SUM(T30:T34) -> 3093.7356
B36: Other Non Current Assets | C36: 1030.9 | D36: 1280.2 | E36: 1948.8 | F36: 1921 | G36: 1760.1 | H36: 1805.4 | I36: 1951.5 | J36: 2414.4 | K36: 2337.4 | L36: 1982.51 | M36: =M25-M35-M44 -> 1872.526 | N36: =N25-N35-N44 -> 1872.526 | O36: =O25-O35-O44 -> 1872.526 | P36: =P25-P35-P44 -> 1872.526 | Q36: =Q25-Q35-Q44 -> 1872.526 | R36: =R25-R35-R44 -> 1872.526 | S36: =S25-S35-S44 -> 1872.526 | T36: =T25-T35-T44 -> 1872.526
B37: Total Non Current Assets | C37: =SUM(C35:C36) -> 3146.8 | D37: =SUM(D35:D36) -> 3220.1 | E37: =SUM(E35:E36) -> 3845.1 | F37: =SUM(F35:F36) -> 3981 | G37: =SUM(G35:G36) -> 3734 | H37: =SUM(H35:H36) -> 3747.9 | I37: =SUM(I35:I36) -> 3526.9 | J37: =SUM(J35:J36) -> 3872 | ... T37: =SUM(T35:T36) -> 4966.2616
B39: Current Assets
B40: Accounts Receivables | C40: 2953.4 | D40: 2711.2 | E40: 2542.5 | F40: 2283.5 | G40: 2187.2 | H40: 2373.6 | I40: 2434 | J40: 3056 | K40: 3410 | L40: 3609 | M40: ='Working Capital Schedule'!M9 -> 3613.6625 | N40: ='Working Capital Schedule'!N9 -> 4259.0396 | O40: ='Working Capital Schedule'!O9 -> 4243.4787 | P40: ='Working Capital Schedule'!P9 -> 4854.2159 | Q40: ='Working Capital Schedule'!Q9 -> 4834.8288 | R40: ='Working Capital Schedule'!R9 -> 5484.0038 | S40: ='Working Capital Schedule'!S9 -> 5505.553 | T40: ='Working Capital Schedule'!T9 -> 6198.325
B41: Inventories | C41: 1927.6 | D41: 1919.7 | E41: 1934.3 | F41: 1927.5 | G41: 2051.9 | H41: 2156.7 | I41: 2230 | J41: 2063 | K41: 2305 | L41: 2668 | M41: ='Working Capital Schedule'!M12 -> 2810.4268 | N41: ='Working Capital Schedule'!N12 -> 3106.2741 | O41: ='Working Capital Schedule'!O12 -> 3224.5958 | P41: ='Working Capital Schedule'!P12 -> 3486.1263 | Q41: ='Working Capital Schedule'!Q12 -> 3660.7928 | R41: ='Working Capital Schedule'!R12 -> 3950.6761 | S41: ='Working Capital Schedule'!S12 -> 4155.5382 | T41: ='Working Capital Schedule'!T12 -> 4477.58
B42: Other Current Assets | C42: 780.8 | D42: 849.2 | E42: 504.1 | F42: 585.8 | G42: 480 | H42: 350.7 | I42: 431.5 | J42: 390 | K42: 584 | L42: 1152 | M42: =L42*(1+Assumptions!E27) -> 1215.36 | N42: =M42*(1+Assumptions!F27) -> 1282.2048 | O42: =N42*(1+Assumptions!G27) -> 1352.7261 | P42: =O42*(1+Assumptions!H27) -> 1427.126 | Q42: =P42*(1+Assumptions!I27) -> 1505.6179 | R42: =Q42*(1+Assumptions!J27) -> 1588.4269 | S42: =R42*(1+Assumptions!K27) -> 1675.7904 | T42: =S42*(1+Assumptions!L27) -> 1767.9589
B43: Cash Balance(Incl. Bank and Current Investments) | C43: 87.3 | D43: 256.1 | E43: 282.9 | F43: 73.5 | G43: 83.9 | H43: 282.4 | I43: 1139.1 | J43: 1868 | K43: 2903 | L43: 3134 | M43: =CS!M22 -> 3031.0785 | N43: =CS!N22 -> 3809.9448 | O43: =CS!O22 -> 4055.3746 | P43: =CS!P22 -> 5013.4263 | Q43: =CS!Q22 -> 5374.4459 | R43: =CS!R22 -> 6423.0317 | S43: =CS!S22 -> 6894.5425 | T43: =CS!T22 -> 8059.4748
B44: Total Current Assets | C44: =SUM(C40:C43) -> 5749.1 | D44: =SUM(D40:D43) -> 5736.2 | E44: =SUM(E40:E43) -> 5263.8 | F44: =SUM(F40:F43) -> 4870.3 | G44: =SUM(G40:G43) -> 4803 | H44: =SUM(H40:H43) -> 5163.4 | I44: =SUM(I40:I43) -> 6234.6 | J44: =SUM(J40:J43) -> 7377 | ... T44: =SUM(T40:T43) -> 20503.339
B46: Total Assets | C46: =C37+C44 -> 8895.9 | D46: =D37+D44 -> 8956.3 | E46: =E37+E44 -> 9108.9 | F46: =F37+F44 -> 8851.3 | G46: =G37+G44 -> 8537 | H46: =H37+H44 -> 8911.3 | I46: =I37+I44 -> 9761.5 | J46: =J37+J44 -> 11249 | ... T46: =T37+T44 -> 25469.6
B49: Test | C49: =C46-C25 -> 0 | D49: =D46-D25 -> 0 | E49: =E46-E25 -> 0 | F49: =F46-F25 -> 0 | G49: =G46-G25 -> 0 | H49: =H46-H25 -> 0 | I49: =I46-I25 -> 0 | J49: =J46-J25 -> 0 | ... T49: =T46-T25 -> 0

Sheet CS
B2: Cash Flow Statement | T2: =BS!T2 -> CURRENTLY RUNNING: BASE SCENARIO
B4: Particulars | C4: 2017 | D4: =C4+1 -> 2018 | E4: =D4+1 -> 2019 | F4: =E4+1 -> 2020 | G4: =F4+1 -> 2021 | H4: =G4+1 -> 2022 | I4: =H4+1 -> 2023 | J4: =I4+1 -> 2024 | K4: =J4+1 -> 2025 | ... T4: =S4+1 -> 2034
A6: x | B6: Net Profit Aafter Tax (PAT) | C6: =PL!C22 -> 93 | D6: =PL!D22 -> 651.9 | E6: =PL!E22 -> 683.6 | F6: =PL!F22 -> 620.6 | G6: =PL!G22 -> 362.1 | H6: =PL!H22 -> 810.6 | I6: =PL!I22 -> 1125.8 | J6: =PL!J22 -> 1408 | ... T6: =PL!T22 -> 3013.605
B7: D&A | C7: =-PL!C13 -> 188.6 | D7: =-PL!D13 -> 192.3 | E7: =-PL!E13 -> 214.7 | F7: =-PL!F13 -> 285.3 | G7: =-PL!G13 -> 299.1 | H7: =-PL!H13 -> 303.8 | I7: =-PL!I13 -> 283 | J7: =-PL!J13 -> 275 | ... T7: =-PL!T13 -> 677.58456
B8: +/- in other non cash items | C8: 227.2 | D8: 358.9 | E8: 103.9 | F8: 3 | G8: 1752.2 | H8: 611.5 | I8: -468.8 | J8: -431.9 | K8: 94.6 | L8: -37 | M8: =-PL!M18-PL!M17 -> -107.87266 | N8: =-PL!N18-PL!N17 -> -88.182942 | O8: =-PL!O18-PL!O17 -> -124.50684 | P8: =-PL!P18-PL!P17 -> -125.01771 | Q8: =-PL!Q18-PL!Q17 -> -170.84808 | R8: =-PL!R18-PL!R17 -> -176.88559 | S8: =-PL!S18-PL!S17 -> -226.57088 | T8: =-PL!T18-PL!T17 -> -237.64062
B9: +/- change in NWC | C9: 138 | D9: =-'Working Capital Schedule'!D21 -> -278 | E9: =-'Working Capital Schedule'!E21 -> -53.9 | F9: =-'Working Capital Schedule'!F21 -> -125.7 | G9: =-'Working Capital Schedule'!G21 -> -595.7 | H9: =-'Working Capital Schedule'!H21 -> -748.5 | I9: =-'Working Capital Schedule'!I21 -> -324.8 | J9: =-'Working Capital Schedule'!J21 -> -133.1 | K9: =-'Working Capital Schedule'!K21 -> -12.6 | ... T9: =-'Working Capital Schedule'!T21 -> 70.579636
A10: x | B10: Cash flow from Operating Activities | C10: =SUM(C6:C9) -> 646.8 | D10: =SUM(D6:D9) -> 925.1 | E10: =SUM(E6:E9) -> 948.3 | F10: =SUM(F6:F9) -> 783.2 | G10: =SUM(G6:G9) -> 1817.7 | H10: =SUM(H6:H9) -> 977.4 | I10: =SUM(I6:I9) -> 615.2 | J10: =SUM(J6:J9) -> 1118 | ... T10: =SUM(T6:T9) -> 3524.1286
B11: Interest Received | C11: 19.7 | D11: 4.2 | E11: 6.4 | F11: 6.2 | G11: 11.1 | H11: 6.4 | I11: 20.4 | J11: 42 | K11: 36 | L11: 67 | M11: =M21*Assumptions!E9 -> 203.71 | N11: =N21*Assumptions!F9 -> 197.0201 | O11: =O21*Assumptions!G9 -> 247.64641 | P11: =P21*Assumptions!H9 -> 263.59935 | Q11: =Q21*Assumptions!I9 -> 325.87271 | R11: =R21*Assumptions!J9 -> 349.33898 | S11: =S21*Assumptions!K9 -> 417.49706 | T11: =T21*Assumptions!L9 -> 448.14526
B12: Capex | C12: -311 | D12: -184.3 | E12: -173 | F12: -211.6 | G12: -158.9 | H12: -134 | I12: -136.6 | J12: -98 | K12: -162 | L12: -181 | M12: =-'Working Schedules'!H42 -> -203.83545 | N12: =-'Working Schedules'!I42 -> -222.18064 | O12: =-'Working Schedules'!J42 -> -239.95509 | P12: =-'Working Schedules'!K42 -> -256.75195 | Q12: =-'Working Schedules'!L42 -> -273.44082 | R12: =-'Working Schedules'!M42 -> -291.21448 | S12: =-'Working Schedules'!N42 -> -310.14342 | T12: =-'Working Schedules'!O42 -> -330.30274
B13: Others | C13: 64 | D13: 284 | E13: 128 | F13: 12 | G13: 35 | H13: -176 | I13: 12 | J13: -262 | K13: -227 | L13: 75 | M13: 0 | N13: 0 | O13: 0 | P13: 0 | Q13: 0 | R13: 0 | S13: 0 | T13: 0
B14: Cash flow from investing activities | C14: =SUM(C11:C13) -> -227.3 | D14: =SUM(D11:D13) -> 103.9 | E14: =SUM(E11:E13) -> -38.6 | F14: =SUM(F11:F13) -> -193.4 | G14: =SUM(G11:G13) -> -112.8 | H14: =SUM(H11:H13) -> -303.6 | I14: =SUM(I11:I13) -> -104.2 | J14: =SUM(J11:J13) -> -318 | ... T14: =SUM(T11:T13) -> 117.84252
B15: Repayment Lease Liabilities | C15: -8.6 | D15: 0 | E15: 0 | F15: -64.5 | G15: -80.7 | H15: -100.2 | I15: -124 | J15: -126 | K15: -137 | L15: -144 | M15: ='Working Schedules'!H9 -> -154.08 | N15: ='Working Schedules'!I9 -> -164.8656 | O15: ='Working Schedules'!J9 -> -176.40619 | P15: ='Working Schedules'!K9 -> -188.75463 | Q15: ='Working Schedules'!L9 -> -201.96745 | R15: ='Working Schedules'!M9 -> -216.10517 | S15: ='Working Schedules'!N9 -> -231.23253 | T15: ='Working Schedules'!O9 -> -247.41881
B16: Interest Paid | C16: -375.2 | D16: -252.8 | E16: -229.3 | F16: -181.1 | G16: -142 | H16: -50.1 | I16: -36.3 | J16: -21 | K16: -40 | L16: -37 | M16: =PL!M17 -> -95.837343 | N16: =PL!N17 -> -108.83716 | O16: =PL!O17 -> -123.13957 | P16: =PL!P17 -> -138.58164 | Q16: =PL!Q17 -> -155.02463 | R16: =PL!R17 -> -172.45339 | S16: =PL!S17 -> -190.92618 | T16: =PL!T17 -> -210.50465
B17: Dividend Paid | C17: 0 | D17: 0 | E17: 0 | F17: 0 | G17: 0 | H17: 0 | I17: 0 | J17: -284 | K17: -355 | L17: -1263 | M17: =-Assumptions!E11*PL!M22 -> -1144.7874 | N17: =-Assumptions!F11*PL!N22 -> -1267.138 | O17: =-Assumptions!G11*PL!O22 -> -1419.4835 | P17: =-Assumptions!H11*PL!P22 -> -1552.8283 | Q17: =-Assumptions!I11*PL!Q22 -> -1667.7608 | R17: =-Assumptions!J11*PL!R22 -> -1769.5792 | S17: =-Assumptions!K11*PL!S22 -> -1900.3871 | T17: =-Assumptions!L11*PL!T22 -> -2019.1154
B18: Others | C18: -86.4 | D18: -607.4 | E18: -653.6 | F18: -553.6 | G18: -1471.8 | H18: -324.9 | I18: 505.9 | J18: 359.9 | K18: -27 | L18: 255 | M18: 0 | N18: 0 | O18: 0 | P18: 0 | Q18: 0 | R18: 0 | S18: 0 | T18: 0
B19: Cash flow from Financing activities | C19: =SUM(C15:C18) -> -470.2 | D19: =SUM(D15:D18) -> -860.2 | E19: =SUM(E15:E18) -> -882.9 | F19: =SUM(F15:F18) -> -799.2 | G19: =SUM(G15:G18) -> -1694.5 | H19: =SUM(H15:H18) -> -475.2 | I19: =SUM(I15:I18) -> 345.6 | J19: =SUM(J15:J18) -> -71.1 | ... T19: =SUM(T15:T18) -> -2477.0388
A20: x | B20: Net change in Cash | C20: =C10+C14+C19 -> -50.7 | D20: =D10+D14+D19 -> 168.8 | E20: =E10+E14+E19 -> 26.8 | F20: =F10+F14+F19 -> -209.4 | G20: =G10+G14+G19 -> 10.4 | H20: =H10+H14+H19 -> 198.6 | I20: =I10+I14+I19 -> 856.6 | J20: =J10+J14+J19 -> 728.9 | ... T20: =T10+T14+T19 -> 1164.9323
B21: Opening Cash Balance | C21: 138 | D21: =C22 -> 87.3 | E21: =D22 -> 256.1 | F21: =E22 -> 282.9 | G21: =F22 -> 73.5 | H21: =G22 -> 83.9 | I21: =H22 -> 282.5 | J21: =I22 -> 1139.1 | K21: =J22 -> 1868 | ... T21: =S22 -> 6894.5425
A22: x | B22: Closing Cash Balance | C22: =C20+C21 -> 87.3 | D22: =D20+D21 -> 256.1 | E22: =E20+E21 -> 282.9 | F22: =F20+F21 -> 73.5 | G22: =G20+G21 -> 83.9 | H22: =H20+H21 -> 282.5 | I22: =I20+I21 -> 1139.1 | J22: =J20+J21 -> 1868 | ... T22: =T20+T21 -> 8059.4748

Sheet Assumptions
B2: Assumptions
B4: Particulars | E4: 2027 | F4: =E4+1 -> 2028 | G4: =F4+1 -> 2029 | H4: =G4+1 -> 2030 | I4: =H4+1 -> 2031 | J4: =I4+1 -> 2032 | K4: =J4+1 -> 2033 | L4: =K4+1 -> 2034
B6: Cost of Goods Sold(COGS)
B7: Employee Cost as % of Sales | E7: 0.06254555 | F7: 0.06254555 | G7: 0.06254555 | H7: 0.06254555 | I7: 0.06254555 | J7: 0.06254555 | K7: 0.06254555 | L7: 0.06254555 | N7: Median of Last 10 Years
B8: Selling and admin as % of Sales | E8: 0.205 | F8: 0.205 | G8: 0.205 | H8: 0.205 | I8: 0.205 | J8: 0.205 | K8: 0.205 | L8: 0.205 | N8: Median of Last 10 Years
